Workbook

Sheet 만두건설
A1: 일용노무비지급명세서 | H1: 기간 | K1: =TEXT(DATE(LEFT(A3,4),RIGHT(A3,2),1),"yyyy""년"" mm""월"" dd""일""") & "부터" & CHAR(10) & TEXT(EOMONTH(DATE(LEFT(A3,4),RIGHT(A3,2),1),0),"yyyy""년"" mm""월"" dd""일""") & "까지" -> 2026년 02월 01일부터 2026년 02월 28일까지 | V1: 상호 | AA1: ㈜ 만두건설(건축)
V2: 현장명 | AA2: 1터널통합관리센터
A3: 2026-02 | V3: 책임자 | AA3: 민용기
A4: 번호 | C4: 성명 | E4: 일당 | G4: 출력현황
G5: {=_xlfn.LET( _xlpm.y, LEFT($A$3,4), _xlpm.m, RIGHT($A$3,2), _xlpm.d, _xlfn.SEQUENCE(1,31,1,1), _xlpm.date, DATE(_xlpm.y, _xlpm.m, _xlpm.d), IF(_xlpm.d<=DAY(EOMONTH(DATE(_xlpm.y,_xlpm.m,1),0)), _xlpm.date, "") )} -> 46054 | H5: 46055 | I5: 46056 | J5: 46057 | K5: 46058 | L5: 46059 | M5: 46060 | N5: 46061 | O5: 46062 | P5: 46063 | Q5: 46064 | R5: 46065 | S5: 46066 | T5: 46067 | U5: 46068 | V5: 46069 | W5: 46070 | X5: 46071 | Y5: 46072 | Z5: 46073 | AA5: 46074 | AB5: 46075 | AC5: 46076 | AD5: 46077 | AE5: 46078 | AF5: 46079 | AG5: 46080 | AH5: 46081 | AL5: 공수 | AN5: 총일수
A6: =ROW()-5 -> 1 | C6: 김철수 | G6: 1 | H6: 1 | I6: 1 | J6: 1 | K6: 1 | L6: 1 | M6: 1 | N6: 1 | O6: 1 | P6: 1 | Q6: 1 | R6: 1 | S6: 1 | T6: 1 | U6: 1 | V6: 1 | W6: 1 | X6: 1 | Y6: 1 | Z6: 1 | AA6: 1 | AB6: 1 | AC6: 1 | AD6: 1 | AE6: 1 | AF6: 1 | AG6: 1 | AH6: 1 | AL6: =IF(SUM(G6:AK6)>0,SUM(G6:AK6),"") -> 28 | AN6: =IF(COUNTA(G6:AK6)>0,COUNTA(G6:AJ6),"") -> 28
A7: =ROW()-5 -> 2 | C7: 이영휘 | AL7: =IF(SUM(G7:AK7)>0,SUM(G7:AK7),"") | AN7: =IF(COUNTA(G7:AK7)>0,COUNTA(G7:AJ7),"")
A8: =ROW()-5 -> 3 | C8: 박민수 | AL8: =IF(SUM(G8:AK8)>0,SUM(G8:AK8),"") | AN8: =IF(COUNTA(G8:AK8)>0,COUNTA(G8:AJ8),"")
A9: =ROW()-5 -> 4 | C9: 최지훈 | AL9: =IF(SUM(G9:AK9)>0,SUM(G9:AK9),"") | AN9: =IF(COUNTA(G9:AK9)>0,COUNTA(G9:AJ9),"")
A10: =ROW()-5 -> 5 | C10: 정수진 | AL10: =IF(SUM(G10:AK10)>0,SUM(G10:AK10),"") | AN10: =IF(COUNTA(G10:AK10)>0,COUNTA(G10:AJ10),"")
A11: =ROW()-5 -> 6 | C11: 이준호 | AL11: =IF(SUM(G11:AK11)>0,SUM(G11:AK11),"") | AN11: =IF(COUNTA(G11:AK11)>0,COUNTA(G11:AJ11),"")
A12: =ROW()-5 -> 7 | C12: 한지민 | AL12: =IF(SUM(G12:AK12)>0,SUM(G12:AK12),"") | AN12: =IF(COUNTA(G12:AK12)>0,COUNTA(G12:AJ12),"")
A13: =ROW()-5 -> 8 | C13: 오세훈 | AL13: =IF(SUM(G13:AK13)>0,SUM(G13:AK13),"") | AN13: =IF(COUNTA(G13:AK13)>0,COUNTA(G13:AJ13),"")
A14: =ROW()-5 -> 9 | C14: 장민재 | AL14: =IF(SUM(G14:AK14)>0,SUM(G14:AK14),"") | AN14: =IF(COUNTA(G14:AK14)>0,COUNTA(G14:AJ14),"")
A15: =ROW()-5 -> 10 | C15: 윤지아 | AL15: =IF(SUM(G15:AK15)>0,SUM(G15:AK15),"") | AN15: =IF(COUNTA(G15:AK15)>0,COUNTA(G15:AJ15),"")
A16: =ROW()-5 -> 11 | C16: 임동현 | AL16: =IF(SUM(G16:AK16)>0,SUM(G16:AK16),"") | AN16: =IF(COUNTA(G16:AK16)>0,COUNTA(G16:AJ16),"")
A17: =ROW()-5 -> 12 | C17: 심유진 | AL17: =IF(SUM(G17:AK17)>0,SUM(G17:AK17),"") | AN17: =IF(COUNTA(G17:AK17)>0,COUNTA(G17:AJ17),"")
A18: =ROW()-5 -> 13 | C18: 조현우 | AL18: =IF(SUM(G18:AK18)>0,SUM(G18:AK18),"") | AN18: =IF(COUNTA(G18:AK18)>0,COUNTA(G18:AJ18),"")
... A22: =ROW()-5 -> 17 | C22: 문지호 | AL22: =IF(SUM(G22:AK22)>0,SUM(G22:AK22),"") | AN22: =IF(COUNTA(G22:AK22)>0,COUNTA(G22:AJ22),"")
A23: =ROW()-5 -> 18 | AL23: =IF(SUM(G23:AK23)>0,SUM(G23:AK23),"") | AN23: =IF(COUNTA(G23:AK23)>0,COUNTA(G23:AJ23),"")
A24: =ROW()-5 -> 19 | AL24: =IF(SUM(G24:AK24)>0,SUM(G24:AK24),"") | AN24: =IF(COUNTA(G24:AK24)>0,COUNTA(G24:AJ24),"")
A25: =ROW()-5 -> 20 | AL25: =IF(SUM(G25:AK25)>0,SUM(G25:AK25),"") | AN25: =IF(COUNTA(G25:AK25)>0,COUNTA(G25:AJ25),"")
A26: =ROW()-5 -> 21 | AL26: =IF(SUM(G26:AK26)>0,SUM(G26:AK26),"") | AN26: =IF(COUNTA(G26:AK26)>0,COUNTA(G26:AJ26),"")
A27: =ROW()-5 -> 22 | AL27: =IF(SUM(G27:AK27)>0,SUM(G27:AK27),"") | AN27: =IF(COUNTA(G27:AK27)>0,COUNTA(G27:AJ27),"")
A28: =ROW()-5 -> 23 | AL28: =IF(SUM(G28:AK28)>0,SUM(G28:AK28),"") | AN28: =IF(COUNTA(G28:AK28)>0,COUNTA(G28:AJ28),"")
A29: =ROW()-5 -> 24 | AL29: =IF(SUM(G29:AK29)>0,SUM(G29:AK29),"") | AN29: =IF(COUNTA(G29:AK29)>0,COUNTA(G29:AJ29),"")
A30: =ROW()-5 -> 25 | AL30: =IF(SUM(G30:AK30)>0,SUM(G30:AK30),"") | AN30: =IF(COUNTA(G30:AK30)>0,COUNTA(G30:AJ30),"")
A31: 합계 | G31: =IF(SUM(G6:G30)>0,SUM(G6:G30),"") -> 1 | H31: =IF(SUM(H6:H30)>0,SUM(H6:H30),"") -> 1 | I31: =IF(SUM(I6:I30)>0,SUM(I6:I30),"") -> 1 | J31: =IF(SUM(J6:J30)>0,SUM(J6:J30),"") -> 1 | K31: =IF(SUM(K6:K30)>0,SUM(K6:K30),"") -> 1 | L31: =IF(SUM(L6:L30)>0,SUM(L6:L30),"") -> 1 | M31: =IF(SUM(M6:M30)>0,SUM(M6:M30),"") -> 1 | N31: =IF(SUM(N6:N30)>0,SUM(N6:N30),"") -> 1 | ... AK31: =IF(SUM(AK6:AK30)>0,SUM(AK6:AK30),"") | AL31: =SUM(AL6:AM30) -> 28 | AN31: =SUM(AN6:AO30) -> 28

Sheet 만두토목
A1: 일용노무비지급명세서 | H1: 기간 | K1: =TEXT(DATE(LEFT(A3,4),RIGHT(A3,2),1),"yyyy""년"" mm""월"" dd""일""") & "부터" & CHAR(10) & TEXT(EOMONTH(DATE(LEFT(A3,4),RIGHT(A3,2),1),0),"yyyy""년"" mm""월"" dd""일""") & "까지" -> 2026년 02월 01일부터 2026년 02월 28일까지 | V1: 상호 | AA1: ㈜ 만두건설(건축)
V2: 현장명 | AA2: 1터널통합관리센터
A3: 2026-02 | V3: 책임자 | AA3: 민용기
A4: 번호 | C4: 성명 | E4: 일당 | G4: 출력현황
G5: {=_xlfn.LET( _xlpm.y, LEFT($A$3,4), _xlpm.m, RIGHT($A$3,2), _xlpm.d, _xlfn.SEQUENCE(1,31,1,1), _xlpm.date, DATE(_xlpm.y, _xlpm.m, _xlpm.d), IF(_xlpm.d<=DAY(EOMONTH(DATE(_xlpm.y,_xlpm.m,1),0)), _xlpm.date, "") )} -> 46054 | H5: 46055 | I5: 46056 | J5: 46057 | K5: 46058 | L5: 46059 | M5: 46060 | N5: 46061 | O5: 46062 | P5: 46063 | Q5: 46064 | R5: 46065 | S5: 46066 | T5: 46067 | U5: 46068 | V5: 46069 | W5: 46070 | X5: 46071 | Y5: 46072 | Z5: 46073 | AA5: 46074 | AB5: 46075 | AC5: 46076 | AD5: 46077 | AE5: 46078 | AF5: 46079 | AG5: 46080 | AH5: 46081 | AL5: 공수 | AN5: 총일수
A6: =ROW()-5 -> 1 | C6: 오세훈 | AL6: =IF(SUM(G6:AK6)>0,SUM(G6:AK6),"") | AN6: =IF(COUNTA(G6:AK6)>0,COUNTA(G6:AJ6),"")
A7: =ROW()-5 -> 2 | C7: 이영휘 | G7: 1 | H7: 1 | I7: 1 | J7: 1 | K7: 1 | L7: 1 | M7: 1 | N7: 1 | O7: 1 | P7: 1 | Q7: 1 | R7: 1 | S7: 1 | T7: 1 | U7: 1 | V7: 1 | W7: 1 | X7: 1 | Y7: 1 | Z7: 1 | AA7: 1 | AB7: 1 | AC7: 1 | AD7: 1 | AE7: 1 | AF7: 1 | AG7: 1 | AH7: 1 | AL7: =IF(SUM(G7:AK7)>0,SUM(G7:AK7),"") -> 28 | AN7: =IF(COUNTA(G7:AK7)>0,COUNTA(G7:AJ7),"") -> 28
A8: =ROW()-5 -> 3 | C8: 정수진 | AL8: =IF(SUM(G8:AK8)>0,SUM(G8:AK8),"") | AN8: =IF(COUNTA(G8:AK8)>0,COUNTA(G8:AJ8),"")
A9: =ROW()-5 -> 4 | C9: 최지훈 | AL9: =IF(SUM(G9:AK9)>0,SUM(G9:AK9),"") | AN9: =IF(COUNTA(G9:AK9)>0,COUNTA(G9:AJ9),"")
A10: =ROW()-5 -> 5 | C10: 이영수 | AL10: =IF(SUM(G10:AK10)>0,SUM(G10:AK10),"") | AN10: =IF(COUNTA(G10:AK10)>0,COUNTA(G10:AJ10),"")
A11: =ROW()-5 -> 6 | C11: 이준호 | AL11: =IF(SUM(G11:AK11)>0,SUM(G11:AK11),"") | AN11: =IF(COUNTA(G11:AK11)>0,COUNTA(G11:AJ11),"")
A12: =ROW()-5 -> 7 | C12: 한지민 | AL12: =IF(SUM(G12:AK12)>0,SUM(G12:AK12),"") | AN12: =IF(COUNTA(G12:AK12)>0,COUNTA(G12:AJ12),"")
A13: =ROW()-5 -> 8 | C13: 이수지 | AL13: =IF(SUM(G13:AK13)>0,SUM(G13:AK13),"") | AN13: =IF(COUNTA(G13:AK13)>0,COUNTA(G13:AJ13),"")
A14: =ROW()-5 -> 9 | C14: 장민재 | AL14: =IF(SUM(G14:AK14)>0,SUM(G14:AK14),"") | AN14: =IF(COUNTA(G14:AK14)>0,COUNTA(G14:AJ14),"")
A15: =ROW()-5 -> 10 | C15: 윤지아 | AL15: =IF(SUM(G15:AK15)>0,SUM(G15:AK15),"") | AN15: =IF(COUNTA(G15:AK15)>0,COUNTA(G15:AJ15),"")
A16: =ROW()-5 -> 11 | C16: 임동현 | AL16: =IF(SUM(G16:AK16)>0,SUM(G16:AK16),"") | AN16: =IF(COUNTA(G16:AK16)>0,COUNTA(G16:AJ16),"")
A17: =ROW()-5 -> 12 | C17: 심유진 | AL17: =IF(SUM(G17:AK17)>0,SUM(G17:AK17),"") | AN17: =IF(COUNTA(G17:AK17)>0,COUNTA(G17:AJ17),"")
A18: =ROW()-5 -> 13 | C18: 조현우 | AL18: =IF(SUM(G18:AK18)>0,SUM(G18:AK18),"") | AN18: =IF(COUNTA(G18:AK18)>0,COUNTA(G18:AJ18),"")
A19: =ROW()-5 -> 14 | C19: 서지은 | AL19: =IF(SUM(G19:AK19)>0,SUM(G19:AK19),"") | AN19: =IF(COUNTA(G19:AK19)>0,COUNTA(G19:AJ19),"")
... A22: =ROW()-5 -> 17 | C22: 문지호 | AL22: =IF(SUM(G22:AK22)>0,SUM(G22:AK22),"") | AN22: =IF(COUNTA(G22:AK22)>0,COUNTA(G22:AJ22),"")
A23: =ROW()-5 -> 18 | AL23: =IF(SUM(G23:AK23)>0,SUM(G23:AK23),"") | AN23: =IF(COUNTA(G23:AK23)>0,COUNTA(G23:AJ23),"")
A24: =ROW()-5 -> 19 | AL24: =IF(SUM(G24:AK24)>0,SUM(G24:AK24),"") | AN24: =IF(COUNTA(G24:AK24)>0,COUNTA(G24:AJ24),"")
A25: =ROW()-5 -> 20 | AL25: =IF(SUM(G25:AK25)>0,SUM(G25:AK25),"") | AN25: =IF(COUNTA(G25:AK25)>0,COUNTA(G25:AJ25),"")
A26: =ROW()-5 -> 21 | AL26: =IF(SUM(G26:AK26)>0,SUM(G26:AK26),"") | AN26: =IF(COUNTA(G26:AK26)>0,COUNTA(G26:AJ26),"")
A27: =ROW()-5 -> 22 | AL27: =IF(SUM(G27:AK27)>0,SUM(G27:AK27),"") | AN27: =IF(COUNTA(G27:AK27)>0,COUNTA(G27:AJ27),"")
A28: =ROW()-5 -> 23 | AL28: =IF(SUM(G28:AK28)>0,SUM(G28:AK28),"") | AN28: =IF(COUNTA(G28:AK28)>0,COUNTA(G28:AJ28),"")
A29: =ROW()-5 -> 24 | AL29: =IF(SUM(G29:AK29)>0,SUM(G29:AK29),"") | AN29: =IF(COUNTA(G29:AK29)>0,COUNTA(G29:AJ29),"")
A30: =ROW()-5 -> 25 | AL30: =IF(SUM(G30:AK30)>0,SUM(G30:AK30),"") | AN30: =IF(COUNTA(G30:AK30)>0,COUNTA(G30:AJ30),"")
A31: 합계 | G31: =IF(SUM(G6:G30)>0,SUM(G6:G30),"") -> 1 | H31: =IF(SUM(H6:H30)>0,SUM(H6:H30),"") -> 1 | I31: =IF(SUM(I6:I30)>0,SUM(I6:I30),"") -> 1 | J31: =IF(SUM(J6:J30)>0,SUM(J6:J30),"") -> 1 | K31: =IF(SUM(K6:K30)>0,SUM(K6:K30),"") -> 1 | L31: =IF(SUM(L6:L30)>0,SUM(L6:L30),"") -> 1 | M31: =IF(SUM(M6:M30)>0,SUM(M6:M30),"") -> 1 | N31: =IF(SUM(N6:N30)>0,SUM(N6:N30),"") -> 1 | ... AK31: =IF(SUM(AK6:AK30)>0,SUM(AK6:AK30),"") | AL31: =SUM(AL6:AM30) -> 28 | AN31: =SUM(AN6:AO30) -> 28

Sheet 홍천서석
A1: 일용노무비지급명세서 | H1: 기간 | K1: =TEXT(DATE(LEFT(A3,4),RIGHT(A3,2),1),"yyyy""년"" mm""월"" dd""일""") & "부터" & CHAR(10) & TEXT(EOMONTH(DATE(LEFT(A3,4),RIGHT(A3,2),1),0),"yyyy""년"" mm""월"" dd""일""") & "까지" -> 2026년 02월 01일부터 2026년 02월 28일까지 | V1: 상호 | AA1: ㈜ 만두건설(건축)
V2: 현장명 | AA2: 1터널통합관리센터
A3: 2026-02 | V3: 책임자 | AA3: 민용기
A4: 번호 | C4: 성명 | E4: 일당 | G4: 출력현황
G5: {=_xlfn.LET( _xlpm.y, LEFT($A$3,4), _xlpm.m, RIGHT($A$3,2), _xlpm.d, _xlfn.SEQUENCE(1,31,1,1), _xlpm.date, DATE(_xlpm.y, _xlpm.m, _xlpm.d), IF(_xlpm.d<=DAY(EOMONTH(DATE(_xlpm.y,_xlpm.m,1),0)), _xlpm.date, "") )} -> 46054 | H5: 46055 | I5: 46056 | J5: 46057 | K5: 46058 | L5: 46059 | M5: 46060 | N5: 46061 | O5: 46062 | P5: 46063 | Q5: 46064 | R5: 46065 | S5: 46066 | T5: 46067 | U5: 46068 | V5: 46069 | W5: 46070 | X5: 46071 | Y5: 46072 | Z5: 46073 | AA5: 46074 | AB5: 46075 | AC5: 46076 | AD5: 46077 | AE5: 46078 | AF5: 46079 | AG5: 46080 | AH5: 46081 | AL5: 공수 | AN5: 총일수
A6: =ROW()-5 -> 1 | C6: 민용기 | AL6: =IF(SUM(G6:AK6)>0,SUM(G6:AK6),"") | AN6: =IF(COUNTA(G6:AK6)>0,COUNTA(G6:AJ6),"")
A7: =ROW()-5 -> 2 | C7: 이영휘 | AL7: =IF(SUM(G7:AK7)>0,SUM(G7:AK7),"") | AN7: =IF(COUNTA(G7:AK7)>0,COUNTA(G7:AJ7),"")
A8: =ROW()-5 -> 3 | C8: 홍준표 | G8: 1 | H8: 1 | I8: 1 | J8: 1 | K8: 1 | L8: 1 | M8: 1 | N8: 1 | O8: 1 | P8: 1 | Q8: 1 | R8: 1 | S8: 1 | T8: 1 | U8: 1 | V8: 1 | W8: 1 | X8: 1 | Y8: 1 | Z8: 1 | AA8: 1 | AB8: 1 | AC8: 1 | AD8: 1 | AE8: 1 | AF8: 1 | AG8: 1 | AH8: 1 | AL8: =IF(SUM(G8:AK8)>0,SUM(G8:AK8),"") -> 28 | AN8: =IF(COUNTA(G8:AK8)>0,COUNTA(G8:AJ8),"") -> 28
A9: =ROW()-5 -> 4 | C9: 최지훈 | AL9: =IF(SUM(G9:AK9)>0,SUM(G9:AK9),"") | AN9: =IF(COUNTA(G9:AK9)>0,COUNTA(G9:AJ9),"")
A10: =ROW()-5 -> 5 | C10: 정수진 | AL10: =IF(SUM(G10:AK10)>0,SUM(G10:AK10),"") | AN10: =IF(COUNTA(G10:AK10)>0,COUNTA(G10:AJ10),"")
A11: =ROW()-5 -> 6 | C11: 이준호 | AL11: =IF(SUM(G11:AK11)>0,SUM(G11:AK11),"") | AN11: =IF(COUNTA(G11:AK11)>0,COUNTA(G11:AJ11),"")
A12: =ROW()-5 -> 7 | C12: 한지민 | AL12: =IF(SUM(G12:AK12)>0,SUM(G12:AK12),"") | AN12: =IF(COUNTA(G12:AK12)>0,COUNTA(G12:AJ12),"")
A13: =ROW()-5 -> 8 | C13: 오세훈 | AL13: =IF(SUM(G13:AK13)>0,SUM(G13:AK13),"") | AN13: =IF(COUNTA(G13:AK13)>0,COUNTA(G13:AJ13),"")
A14: =ROW()-5 -> 9 | C14: 이 | AL14: =IF(SUM(G14:AK14)>0,SUM(G14:AK14),"") | AN14: =IF(COUNTA(G14:AK14)>0,COUNTA(G14:AJ14),"")
A15: =ROW()-5 -> 10 | C15: 윤지아 | AL15: =IF(SUM(G15:AK15)>0,SUM(G15:AK15),"") | AN15: =IF(COUNTA(G15:AK15)>0,COUNTA(G15:AJ15),"")
A16: =ROW()-5 -> 11 | C16: 임동현 | AL16: =IF(SUM(G16:AK16)>0,SUM(G16:AK16),"") | AN16: =IF(COUNTA(G16:AK16)>0,COUNTA(G16:AJ16),"")
A17: =ROW()-5 -> 12 | C17: 심유진 | AL17: =IF(SUM(G17:AK17)>0,SUM(G17:AK17),"") | AN17: =IF(COUNTA(G17:AK17)>0,COUNTA(G17:AJ17),"")
A18: =ROW()-5 -> 13 | C18: 조현우 | AL18: =IF(SUM(G18:AK18)>0,SUM(G18:AK18),"") | AN18: =IF(COUNTA(G18:AK18)>0,COUNTA(G18:AJ18),"")
A19: =ROW()-5 -> 14 | C19: 이서진 | AL19: =IF(SUM(G19:AK19)>0,SUM(G19:AK19),"") | AN19: =IF(COUNTA(G19:AK19)>0,COUNTA(G19:AJ19),"")
A20: =ROW()-5 -> 15 | C20: 백승민 | AL20: =IF(SUM(G20:AK20)>0,SUM(G20:AK20),"") | AN20: =IF(COUNTA(G20:AK20)>0,COUNTA(G20:AJ20),"")
... A22: =ROW()-5 -> 17 | C22: 김문수 | AL22: =IF(SUM(G22:AK22)>0,SUM(G22:AK22),"") | AN22: =IF(COUNTA(G22:AK22)>0,COUNTA(G22:AJ22),"")
A23: =ROW()-5 -> 18 | AL23: =IF(SUM(G23:AK23)>0,SUM(G23:AK23),"") | AN23: =IF(COUNTA(G23:AK23)>0,COUNTA(G23:AJ23),"")
A24: =ROW()-5 -> 19 | AL24: =IF(SUM(G24:AK24)>0,SUM(G24:AK24),"") | AN24: =IF(COUNTA(G24:AK24)>0,COUNTA(G24:AJ24),"")
A25: =ROW()-5 -> 20 | AL25: =IF(SUM(G25:AK25)>0,SUM(G25:AK25),"") | AN25: =IF(COUNTA(G25:AK25)>0,COUNTA(G25:AJ25),"")
A26: =ROW()-5 -> 21 | AL26: =IF(SUM(G26:AK26)>0,SUM(G26:AK26),"") | AN26: =IF(COUNTA(G26:AK26)>0,COUNTA(G26:AJ26),"")
A27: =ROW()-5 -> 22 | AL27: =IF(SUM(G27:AK27)>0,SUM(G27:AK27),"") | AN27: =IF(COUNTA(G27:AK27)>0,COUNTA(G27:AJ27),"")
A28: =ROW()-5 -> 23 | AL28: =IF(SUM(G28:AK28)>0,SUM(G28:AK28),"") | AN28: =IF(COUNTA(G28:AK28)>0,COUNTA(G28:AJ28),"")
A29: =ROW()-5 -> 24 | AL29: =IF(SUM(G29:AK29)>0,SUM(G29:AK29),"") | AN29: =IF(COUNTA(G29:AK29)>0,COUNTA(G29:AJ29),"")
A30: =ROW()-5 -> 25 | AL30: =IF(SUM(G30:AK30)>0,SUM(G30:AK30),"") | AN30: =IF(COUNTA(G30:AK30)>0,COUNTA(G30:AJ30),"")
A31: 합계 | G31: =IF(SUM(G6:G30)>0,SUM(G6:G30),"") -> 1 | H31: =IF(SUM(H6:H30)>0,SUM(H6:H30),"") -> 1 | I31: =IF(SUM(I6:I30)>0,SUM(I6:I30),"") -> 1 | J31: =IF(SUM(J6:J30)>0,SUM(J6:J30),"") -> 1 | K31: =IF(SUM(K6:K30)>0,SUM(K6:K30),"") -> 1 | L31: =IF(SUM(L6:L30)>0,SUM(L6:L30),"") -> 1 | M31: =IF(SUM(M6:M30)>0,SUM(M6:M30),"") -> 1 | N31: =IF(SUM(N6:N30)>0,SUM(N6:N30),"") -> 1 | ... AK31: =IF(SUM(AK6:AK30)>0,SUM(AK6:AK30),"") | AL31: =SUM(AL6:AM30) -> 28 | AN31: =SUM(AN6:AO30) -> 28

Sheet 사창리
A1: 일용노무비지급명세서 | H1: 기간 | K1: =TEXT(DATE(LEFT(A3,4),RIGHT(A3,2),1),"yyyy""년"" mm""월"" dd""일""") & "부터" & CHAR(10) & TEXT(EOMONTH(DATE(LEFT(A3,4),RIGHT(A3,2),1),0),"yyyy""년"" mm""월"" dd""일""") & "까지" -> 2026년 02월 01일부터 2026년 02월 28일까지 | V1: 상호 | AA1: ㈜ 만두건설(건축)
V2: 현장명 | AA2: 1터널통합관리센터
A3: 2026-02 | V3: 책임자 | AA3: 민용기
A4: 번호 | C4: 성명 | E4: 일당 | G4: 출력현황
G5: {=_xlfn.LET( _xlpm.y, LEFT($A$3,4), _xlpm.m, RIGHT($A$3,2), _xlpm.d, _xlfn.SEQUENCE(1,31,1,1), _xlpm.date, DATE(_xlpm.y, _xlpm.m, _xlpm.d), IF(_xlpm.d<=DAY(EOMONTH(DATE(_xlpm.y,_xlpm.m,1),0)), _xlpm.date, "") )} -> 46054 | H5: 46055 | I5: 46056 | J5: 46057 | K5: 46058 | L5: 46059 | M5: 46060 | N5: 46061 | O5: 46062 | P5: 46063 | Q5: 46064 | R5: 46065 | S5: 46066 | T5: 46067 | U5: 46068 | V5: 46069 | W5: 46070 | X5: 46071 | Y5: 46072 | Z5: 46073 | AA5: 46074 | AB5: 46075 | AC5: 46076 | AD5: 46077 | AE5: 46078 | AF5: 46079 | AG5: 46080 | AH5: 46081 | AL5: 공수 | AN5: 총일수
A6: =ROW()-5 -> 1 | C6: 이광휘 | AL6: =IF(SUM(G6:AK6)>0,SUM(G6:AK6),"") | AN6: =IF(COUNTA(G6:AK6)>0,COUNTA(G6:AJ6),"")
A7: =ROW()-5 -> 2 | C7: 이영휘 | AL7: =IF(SUM(G7:AK7)>0,SUM(G7:AK7),"") | AN7: =IF(COUNTA(G7:AK7)>0,COUNTA(G7:AJ7),"")
A8: =ROW()-5 -> 3 | C8: 박민수 | AL8: =IF(SUM(G8:AK8)>0,SUM(G8:AK8),"") | AN8: =IF(COUNTA(G8:AK8)>0,COUNTA(G8:AJ8),"")
A9: =ROW()-5 -> 4 | C9: 최지훈 | G9: 1 | H9: 1 | I9: 1 | J9: 1 | K9: 1 | L9: 1 | M9: 1 | N9: 1 | O9: 1 | P9: 1 | Q9: 1 | R9: 1 | S9: 1 | T9: 1 | U9: 1 | V9: 1 | W9: 1 | X9: 1 | Y9: 1 | Z9: 1 | AA9: 1 | AB9: 1 | AC9: 1 | AD9: 1 | AE9: 1 | AF9: 1 | AG9: 1 | AH9: 1 | AL9: =IF(SUM(G9:AK9)>0,SUM(G9:AK9),"") -> 28 | AN9: =IF(COUNTA(G9:AK9)>0,COUNTA(G9:AJ9),"") -> 28
A10: =ROW()-5 -> 5 | C10: 서인철 | AL10: =IF(SUM(G10:AK10)>0,SUM(G10:AK10),"") | AN10: =IF(COUNTA(G10:AK10)>0,COUNTA(G10:AJ10),"")
A11: =ROW()-5 -> 6 | C11: 이준호 | AL11: =IF(SUM(G11:AK11)>0,SUM(G11:AK11),"") | AN11: =IF(COUNTA(G11:AK11)>0,COUNTA(G11:AJ11),"")
A12: =ROW()-5 -> 7 | C12: 한지민 | AL12: =IF(SUM(G12:AK12)>0,SUM(G12:AK12),"") | AN12: =IF(COUNTA(G12:AK12)>0,COUNTA(G12:AJ12),"")
A13: =ROW()-5 -> 8 | C13: 오세훈 | AL13: =IF(SUM(G13:AK13)>0,SUM(G13:AK13),"") | AN13: =IF(COUNTA(G13:AK13)>0,COUNTA(G13:AJ13),"")
A14: =ROW()-5 -> 9 | C14: 장민재 | AL14: =IF(SUM(G14:AK14)>0,SUM(G14:AK14),"") | AN14: =IF(COUNTA(G14:AK14)>0,COUNTA(G14:AJ14),"")
A15: =ROW()-5 -> 10 | C15: 문준호 | AL15: =IF(SUM(G15:AK15)>0,SUM(G15:AK15),"") | AN15: =IF(COUNTA(G15:AK15)>0,COUNTA(G15:AJ15),"")
A16: =ROW()-5 -> 11 | C16: 임동현 | AL16: =IF(SUM(G16:AK16)>0,SUM(G16:AK16),"") | AN16: =IF(COUNTA(G16:AK16)>0,COUNTA(G16:AJ16),"")
A17: =ROW()-5 -> 12 | C17: 심유진 | AL17: =IF(SUM(G17:AK17)>0,SUM(G17:AK17),"") | AN17: =IF(COUNTA(G17:AK17)>0,COUNTA(G17:AJ17),"")
A18: =ROW()-5 -> 13 | C18: 조현우 | AL18: =IF(SUM(G18:AK18)>0,SUM(G18:AK18),"") | AN18: =IF(COUNTA(G18:AK18)>0,COUNTA(G18:AJ18),"")
A19: =ROW()-5 -> 14 | C19: 서지은 | AL19: =IF(SUM(G19:AK19)>0,SUM(G19:AK19),"") | AN19: =IF(COUNTA(G19:AK19)>0,COUNTA(G19:AJ19),"")
A20: =ROW()-5 -> 15 | C20: 이동훈 | AL20: =IF(SUM(G20:AK20)>0,SUM(G20:AK20),"") | AN20: =IF(COUNTA(G20:AK20)>0,COUNTA(G20:AJ20),"")
A21: =ROW()-5 -> 16 | C21: 강다연 | AL21: =IF(SUM(G21:AK21)>0,SUM(G21:AK21),"") | AN21: =IF(COUNTA(G21:AK21)>0,COUNTA(G21:AJ21),"")
A22: =ROW()-5 -> 17 | C22: 문지호 | AL22: =IF(SUM(G22:AK22)>0,SUM(G22:AK22),"") | AN22: =IF(COUNTA(G22:AK22)>0,COUNTA(G22:AJ22),"")
A23: =ROW()-5 -> 18 | AL23: =IF(SUM(G23:AK23)>0,SUM(G23:AK23),"") | AN23: =IF(COUNTA(G23:AK23)>0,COUNTA(G23:AJ23),"")
A24: =ROW()-5 -> 19 | AL24: =IF(SUM(G24:AK24)>0,SUM(G24:AK24),"") | AN24: =IF(COUNTA(G24:AK24)>0,COUNTA(G24:AJ24),"")
A25: =ROW()-5 -> 20 | AL25: =IF(SUM(G25:AK25)>0,SUM(G25:AK25),"") | AN25: =IF(COUNTA(G25:AK25)>0,COUNTA(G25:AJ25),"")
A26: =ROW()-5 -> 21 | AL26: =IF(SUM(G26:AK26)>0,SUM(G26:AK26),"") | AN26: =IF(COUNTA(G26:AK26)>0,COUNTA(G26:AJ26),"")
A27: =ROW()-5 -> 22 | AL27: =IF(SUM(G27:AK27)>0,SUM(G27:AK27),"") | AN27: =IF(COUNTA(G27:AK27)>0,COUNTA(G27:AJ27),"")
A28: =ROW()-5 -> 23 | AL28: =IF(SUM(G28:AK28)>0,SUM(G28:AK28),"") | AN28: =IF(COUNTA(G28:AK28)>0,COUNTA(G28:AJ28),"")
A29: =ROW()-5 -> 24 | AL29: =IF(SUM(G29:AK29)>0,SUM(G29:AK29),"") | AN29: =IF(COUNTA(G29:AK29)>0,COUNTA(G29:AJ29),"")
A30: =ROW()-5 -> 25 | AL30: =IF(SUM(G30:AK30)>0,SUM(G30:AK30),"") | AN30: =IF(COUNTA(G30:AK30)>0,COUNTA(G30:AJ30),"")
A31: 합계 | G31: =IF(SUM(G6:G30)>0,SUM(G6:G30),"") -> 1 | H31: =IF(SUM(H6:H30)>0,SUM(H6:H30),"") -> 1 | I31: =IF(SUM(I6:I30)>0,SUM(I6:I30),"") -> 1 | J31: =IF(SUM(J6:J30)>0,SUM(J6:J30),"") -> 1 | K31: =IF(SUM(K6:K30)>0,SUM(K6:K30),"") -> 1 | L31: =IF(SUM(L6:L30)>0,SUM(L6:L30),"") -> 1 | M31: =IF(SUM(M6:M30)>0,SUM(M6:M30),"") -> 1 | N31: =IF(SUM(N6:N30)>0,SUM(N6:N30),"") -> 1 | ... AK31: =IF(SUM(AK6:AK30)>0,SUM(AK6:AK30),"") | AL31: =SUM(AL6:AM30) -> 28 | AN31: =SUM(AN6:AO30) -> 28

Sheet 대원건설
A1: 일용노무비지급명세서 | H1: 기간 | K1: =TEXT(DATE(LEFT(A3,4),RIGHT(A3,2),1),"yyyy""년"" mm""월"" dd""일""") & "부터" & CHAR(10) & TEXT(EOMONTH(DATE(LEFT(A3,4),RIGHT(A3,2),1),0),"yyyy""년"" mm""월"" dd""일""") & "까지" -> 2026년 02월 01일부터 2026년 02월 28일까지 | V1: 상호 | AA1: ㈜ 만두건설(건축)
V2: 현장명 | AA2: 1터널통합관리센터
A3: 2026-02 | V3: 책임자 | AA3: 민용기
A4: 번호 | C4: 성명 | E4: 일당 | G4: 출력현황
G5: {=_xlfn.LET( _xlpm.y, LEFT($A$3,4), _xlpm.m, RIGHT($A$3,2), _xlpm.d, _xlfn.SEQUENCE(1,31,1,1), _xlpm.date, DATE(_xlpm.y, _xlpm.m, _xlpm.d), IF(_xlpm.d<=DAY(EOMONTH(DATE(_xlpm.y,_xlpm.m,1),0)), _xlpm.date, "") )} -> 46054 | H5: 46055 | I5: 46056 | J5: 46057 | K5: 46058 | L5: 46059 | M5: 46060 | N5: 46061 | O5: 46062 | P5: 46063 | Q5: 46064 | R5: 46065 | S5: 46066 | T5: 46067 | U5: 46068 | V5: 46069 | W5: 46070 | X5: 46071 | Y5: 46072 | Z5: 46073 | AA5: 46074 | AB5: 46075 | AC5: 46076 | AD5: 46077 | AE5: 46078 | AF5: 46079 | AG5: 46080 | AH5: 46081 | AL5: 공수 | AN5: 총일수
A6: =ROW()-5 -> 1 | C6: 김철수 | AL6: =IF(SUM(G6:AK6)>0,SUM(G6:AK6),"") | AN6: =IF(COUNTA(G6:AK6)>0,COUNTA(G6:AJ6),"")
A7: =ROW()-5 -> 2 | C7: 이영휘 | AL7: =IF(SUM(G7:AK7)>0,SUM(G7:AK7),"") | AN7: =IF(COUNTA(G7:AK7)>0,COUNTA(G7:AJ7),"")
A8: =ROW()-5 -> 3 | C8: 박민수 | AL8: =IF(SUM(G8:AK8)>0,SUM(G8:AK8),"") | AN8: =IF(COUNTA(G8:AK8)>0,COUNTA(G8:AJ8),"")
A9: =ROW()-5 -> 4 | C9: 최지훈 | AL9: =IF(SUM(G9:AK9)>0,SUM(G9:AK9),"") | AN9: =IF(COUNTA(G9:AK9)>0,COUNTA(G9:AJ9),"")
A10: =ROW()-5 -> 5 | C10: 정수진 | G10: 1 | H10: 1 | I10: 1 | J10: 1 | K10: 1 | L10: 1 | M10: 1 | N10: 1 | O10: 1 | P10: 1 | Q10: 1 | R10: 1 | S10: 1 | T10: 1 | U10: 1 | V10: 1 | W10: 1 | X10: 1 | Y10: 1 | Z10: 1 | AA10: 1 | AB10: 1 | AC10: 1 | AD10: 1 | AE10: 1 | AF10: 1 | AG10: 1 | AH10: 1 | AL10: =IF(SUM(G10:AK10)>0,SUM(G10:AK10),"") -> 28 | AN10: =IF(COUNTA(G10:AK10)>0,COUNTA(G10:AJ10),"") -> 28
A11: =ROW()-5 -> 6 | C11: 이준호 | AL11: =IF(SUM(G11:AK11)>0,SUM(G11:AK11),"") | AN11: =IF(COUNTA(G11:AK11)>0,COUNTA(G11:AJ11),"")
A12: =ROW()-5 -> 7 | C12: 한지민 | AL12: =IF(SUM(G12:AK12)>0,SUM(G12:AK12),"") | AN12: =IF(COUNTA(G12:AK12)>0,COUNTA(G12:AJ12),"")
A13: =ROW()-5 -> 8 | C13: 오세훈 | AL13: =IF(SUM(G13:AK13)>0,SUM(G13:AK13),"") | AN13: =IF(COUNTA(G13:AK13)>0,COUNTA(G13:AJ13),"")
A14: =ROW()-5 -> 9 | C14: 장민재 | AL14: =IF(SUM(G14:AK14)>0,SUM(G14:AK14),"") | AN14: =IF(COUNTA(G14:AK14)>0,COUNTA(G14:AJ14),"")
A15: =ROW()-5 -> 10 | C15: 윤지아 | AL15: =IF(SUM(G15:AK15)>0,SUM(G15:AK15),"") | AN15: =IF(COUNTA(G15:AK15)>0,COUNTA(G15:AJ15),"")
A16: =ROW()-5 -> 11 | C16: 임동현 | AL16: =IF(SUM(G16:AK16)>0,SUM(G16:AK16),"") | AN16: =IF(COUNTA(G16:AK16)>0,COUNTA(G16:AJ16),"")
A17: =ROW()-5 -> 12 | C17: 심유진 | AL17: =IF(SUM(G17:AK17)>0,SUM(G17:AK17),"") | AN17: =IF(COUNTA(G17:AK17)>0,COUNTA(G17:AJ17),"")
A18: =ROW()-5 -> 13 | C18: 조현우 | AL18: =IF(SUM(G18:AK18)>0,SUM(G18:AK18),"") | AN18: =IF(COUNTA(G18:AK18)>0,COUNTA(G18:AJ18),"")
A19: =ROW()-5 -> 14 | C19: 서지은 | AL19: =IF(SUM(G19:AK19)>0,SUM(G19:AK19),"") | AN19: =IF(COUNTA(G19:AK19)>0,COUNTA(G19:AJ19),"")
A20: =ROW()-5 -> 15 | C20: 백승민 | AL20: =IF(SUM(G20:AK20)>0,SUM(G20:AK20),"") | AN20: =IF(COUNTA(G20:AK20)>0,COUNTA(G20:AJ20),"")
A21: =ROW()-5 -> 16 | C21: 강다연 | AL21: =IF(SUM(G21:AK21)>0,SUM(G21:AK21),"") | AN21: =IF(COUNTA(G21:AK21)>0,COUNTA(G21:AJ21),"")
A22: =ROW()-5 -> 17 | C22: 문지호 | AL22: =IF(SUM(G22:AK22)>0,SUM(G22:AK22),"") | AN22: =IF(COUNTA(G22:AK22)>0,COUNTA(G22:AJ22),"")
A23: =ROW()-5 -> 18 | AL23: =IF(SUM(G23:AK23)>0,SUM(G23:AK23),"") | AN23: =IF(COUNTA(G23:AK23)>0,COUNTA(G23:AJ23),"")
A24: =ROW()-5 -> 19 | AL24: =IF(SUM(G24:AK24)>0,SUM(G24:AK24),"") | AN24: =IF(COUNTA(G24:AK24)>0,COUNTA(G24:AJ24),"")
A25: =ROW()-5 -> 20 | AL25: =IF(SUM(G25:AK25)>0,SUM(G25:AK25),"") | AN25: =IF(COUNTA(G25:AK25)>0,COUNTA(G25:AJ25),"")
A26: =ROW()-5 -> 21 | AL26: =IF(SUM(G26:AK26)>0,SUM(G26:AK26),"") | AN26: =IF(COUNTA(G26:AK26)>0,COUNTA(G26:AJ26),"")
A27: =ROW()-5 -> 22 | AL27: =IF(SUM(G27:AK27)>0,SUM(G27:AK27),"") | AN27: =IF(COUNTA(G27:AK27)>0,COUNTA(G27:AJ27),"")
A28: =ROW()-5 -> 23 | AL28: =IF(SUM(G28:AK28)>0,SUM(G28:AK28),"") | AN28: =IF(COUNTA(G28:AK28)>0,COUNTA(G28:AJ28),"")
A29: =ROW()-5 -> 24 | AL29: =IF(SUM(G29:AK29)>0,SUM(G29:AK29),"") | AN29: =IF(COUNTA(G29:AK29)>0,COUNTA(G29:AJ29),"")
A30: =ROW()-5 -> 25 | AL30: =IF(SUM(G30:AK30)>0,SUM(G30:AK30),"") | AN30: =IF(COUNTA(G30:AK30)>0,COUNTA(G30:AJ30),"")
A31: 합계 | G31: =IF(SUM(G6:G30)>0,SUM(G6:G30),"") -> 1 | H31: =IF(SUM(H6:H30)>0,SUM(H6:H30),"") -> 1 | I31: =IF(SUM(I6:I30)>0,SUM(I6:I30),"") -> 1 | J31: =IF(SUM(J6:J30)>0,SUM(J6:J30),"") -> 1 | K31: =IF(SUM(K6:K30)>0,SUM(K6:K30),"") -> 1 | L31: =IF(SUM(L6:L30)>0,SUM(L6:L30),"") -> 1 | M31: =IF(SUM(M6:M30)>0,SUM(M6:M30),"") -> 1 | N31: =IF(SUM(N6:N30)>0,SUM(N6:N30),"") -> 1 | ... AK31: =IF(SUM(AK6:AK30)>0,SUM(AK6:AK30),"") | AL31: =SUM(AL6:AM30) -> 28 | AN31: =SUM(AN6:AO30) -> 28

Sheet 정윤일
A1: 일용노무비지급명세서 | H1: 기간 | K1: =TEXT(DATE(LEFT(A3,4),RIGHT(A3,2),1),"yyyy""년"" mm""월"" dd""일""") & "부터" & CHAR(10) & TEXT(EOMONTH(DATE(LEFT(A3,4),RIGHT(A3,2),1),0),"yyyy""년"" mm""월"" dd""일""") & "까지" -> 2026년 02월 01일부터 2026년 02월 28일까지 | V1: 상호 | AA1: ㈜ 만두건설(건축)
V2: 현장명 | AA2: 1터널통합관리센터
A3: 2026-02 | V3: 책임자 | AA3: 민용기
A4: 번호 | C4: 성명 | E4: 일당 | G4: 출력현황
G5: {=_xlfn.LET( _xlpm.y, LEFT($A$3,4), _xlpm.m, RIGHT($A$3,2), _xlpm.d, _xlfn.SEQUENCE(1,31,1,1), _xlpm.date, DATE(_xlpm.y, _xlpm.m, _xlpm.d), IF(_xlpm.d<=DAY(EOMONTH(DATE(_xlpm.y,_xlpm.m,1),0)), _xlpm.date, "") )} -> 46054 | H5: 46055 | I5: 46056 | J5: 46057 | K5: 46058 | L5: 46059 | M5: 46060 | N5: 46061 | O5: 46062 | P5: 46063 | Q5: 46064 | R5: 46065 | S5: 46066 | T5: 46067 | U5: 46068 | V5: 46069 | W5: 46070 | X5: 46071 | Y5: 46072 | Z5: 46073 | AA5: 46074 | AB5: 46075 | AC5: 46076 | AD5: 46077 | AE5: 46078 | AF5: 46079 | AG5: 46080 | AH5: 46081 | AL5: 공수 | AN5: 총일수
A6: =ROW()-5 -> 1 | C6: 김철수 | AL6: =IF(SUM(G6:AK6)>0,SUM(G6:AK6),"") | AN6: =IF(COUNTA(G6:AK6)>0,COUNTA(G6:AJ6),"")
A7: =ROW()-5 -> 2 | C7: 이영휘 | AL7: =IF(SUM(G7:AK7)>0,SUM(G7:AK7),"") | AN7: =IF(COUNTA(G7:AK7)>0,COUNTA(G7:AJ7),"")
A8: =ROW()-5 -> 3 | C8: 박민수 | AL8: =IF(SUM(G8:AK8)>0,SUM(G8:AK8),"") | AN8: =IF(COUNTA(G8:AK8)>0,COUNTA(G8:AJ8),"")
A9: =ROW()-5 -> 4 | C9: 최지훈 | AL9: =IF(SUM(G9:AK9)>0,SUM(G9:AK9),"") | AN9: =IF(COUNTA(G9:AK9)>0,COUNTA(G9:AJ9),"")
A10: =ROW()-5 -> 5 | C10: 정수진 | AL10: =IF(SUM(G10:AK10)>0,SUM(G10:AK10),"") | AN10: =IF(COUNTA(G10:AK10)>0,COUNTA(G10:AJ10),"")
A11: =ROW()-5 -> 6 | C11: 이준호 | G11: 1 | H11: 1 | I11: 1 | J11: 1 | K11: 1 | L11: 1 | M11: 1 | N11: 1 | O11: 1 | P11: 1 | Q11: 1 | R11: 1 | S11: 1 | T11: 1 | U11: 1 | V11: 1 | W11: 1 | X11: 1 | Y11: 1 | Z11: 1 | AA11: 1 | AB11: 1 | AC11: 1 | AD11: 1 | AE11: 1 | AF11: 1 | AG11: 1 | AH11: 1 | AL11: =IF(SUM(G11:AK11)>0,SUM(G11:AK11),"") -> 28 | AN11: =IF(COUNTA(G11:AK11)>0,COUNTA(G11:AJ11),"") -> 28
A12: =ROW()-5 -> 7 | C12: 한지민 | AL12: =IF(SUM(G12:AK12)>0,SUM(G12:AK12),"") | AN12: =IF(COUNTA(G12:AK12)>0,COUNTA(G12:AJ12),"")
A13: =ROW()-5 -> 8 | C13: 오세훈 | AL13: =IF(SUM(G13:AK13)>0,SUM(G13:AK13),"") | AN13: =IF(COUNTA(G13:AK13)>0,COUNTA(G13:AJ13),"")
A14: =ROW()-5 -> 9 | C14: 장민재 | AL14: =IF(SUM(G14:AK14)>0,SUM(G14:AK14),"") | AN14: =IF(COUNTA(G14:AK14)>0,COUNTA(G14:AJ14),"")
A15: =ROW()-5 -> 10 | C15: 윤지아 | AL15: =IF(SUM(G15:AK15)>0,SUM(G15:AK15),"") | AN15: =IF(COUNTA(G15:AK15)>0,COUNTA(G15:AJ15),"")
A16: =ROW()-5 -> 11 | C16: 임동현 | AL16: =IF(SUM(G16:AK16)>0,SUM(G16:AK16),"") | AN16: =IF(COUNTA(G16:AK16)>0,COUNTA(G16:AJ16),"")
A17: =ROW()-5 -> 12 | C17: 심유진 | AL17: =IF(SUM(G17:AK17)>0,SUM(G17:AK17),"") | AN17: =IF(COUNTA(G17:AK17)>0,COUNTA(G17:AJ17),"")
A18: =ROW()-5 -> 13 | C18: 조현우 | AL18: =IF(SUM(G18:AK18)>0,SUM(G18:AK18),"") | AN18: =IF(COUNTA(G18:AK18)>0,COUNTA(G18:AJ18),"")
A19: =ROW()-5 -> 14 | C19: 서지은 | AL19: =IF(SUM(G19:AK19)>0,SUM(G19:AK19),"") | AN19: =IF(COUNTA(G19:AK19)>0,COUNTA(G19:AJ19),"")
A20: =ROW()-5 -> 15 | C20: 백승민 | AL20: =IF(SUM(G20:AK20)>0,SUM(G20:AK20),"") | AN20: =IF(COUNTA(G20:AK20)>0,COUNTA(G20:AJ20),"")
A21: =ROW()-5 -> 16 | C21: 강다연 | AL21: =IF(SUM(G21:AK21)>0,SUM(G21:AK21),"") | AN21: =IF(COUNTA(G21:AK21)>0,COUNTA(G21:AJ21),"")
A22: =ROW()-5 -> 17 | C22: 문지호 | AL22: =IF(SUM(G22:AK22)>0,SUM(G22:AK22),"") | AN22: =IF(COUNTA(G22:AK22)>0,COUNTA(G22:AJ22),"")
A23: =ROW()-5 -> 18 | AL23: =IF(SUM(G23:AK23)>0,SUM(G23:AK23),"") | AN23: =IF(COUNTA(G23:AK23)>0,COUNTA(G23:AJ23),"")
A24: =ROW()-5 -> 19 | AL24: =IF(SUM(G24:AK24)>0,SUM(G24:AK24),"") | AN24: =IF(COUNTA(G24:AK24)>0,COUNTA(G24:AJ24),"")
A25: =ROW()-5 -> 20 | AL25: =IF(SUM(G25:AK25)>0,SUM(G25:AK25),"") | AN25: =IF(COUNTA(G25:AK25)>0,COUNTA(G25:AJ25),"")
A26: =ROW()-5 -> 21 | AL26: =IF(SUM(G26:AK26)>0,SUM(G26:AK26),"") | AN26: =IF(COUNTA(G26:AK26)>0,COUNTA(G26:AJ26),"")
A27: =ROW()-5 -> 22 | AL27: =IF(SUM(G27:AK27)>0,SUM(G27:AK27),"") | AN27: =IF(COUNTA(G27:AK27)>0,COUNTA(G27:AJ27),"")
A28: =ROW()-5 -> 23 | AL28: =IF(SUM(G28:AK28)>0,SUM(G28:AK28),"") | AN28: =IF(COUNTA(G28:AK28)>0,COUNTA(G28:AJ28),"")
A29: =ROW()-5 -> 24 | AL29: =IF(SUM(G29:AK29)>0,SUM(G29:AK29),"") | AN29: =IF(COUNTA(G29:AK29)>0,COUNTA(G29:AJ29),"")
A30: =ROW()-5 -> 25 | AL30: =IF(SUM(G30:AK30)>0,SUM(G30:AK30),"") | AN30: =IF(COUNTA(G30:AK30)>0,COUNTA(G30:AJ30),"")
A31: 합계 | G31: =IF(SUM(G6:G30)>0,SUM(G6:G30),"") -> 1 | H31: =IF(SUM(H6:H30)>0,SUM(H6:H30),"") -> 1 | I31: =IF(SUM(I6:I30)>0,SUM(I6:I30),"") -> 1 | J31: =IF(SUM(J6:J30)>0,SUM(J6:J30),"") -> 1 | K31: =IF(SUM(K6:K30)>0,SUM(K6:K30),"") -> 1 | L31: =IF(SUM(L6:L30)>0,SUM(L6:L30),"") -> 1 | M31: =IF(SUM(M6:M30)>0,SUM(M6:M30),"") -> 1 | N31: =IF(SUM(N6:N30)>0,SUM(N6:N30),"") -> 1 | ... AK31: =IF(SUM(AK6:AK30)>0,SUM(AK6:AK30),"") | AL31: =SUM(AL6:AM30) -> 28 | AN31: =SUM(AN6:AO30) -> 28

Sheet 비고1
A1: 일용노무비지급명세서 | H1: 기간 | K1: =TEXT(DATE(LEFT(A3,4),RIGHT(A3,2),1),"yyyy""년"" mm""월"" dd""일""") & "부터" & CHAR(10) & TEXT(EOMONTH(DATE(LEFT(A3,4),RIGHT(A3,2),1),0),"yyyy""년"" mm""월"" dd""일""") & "까지" -> 2026년 02월 01일부터 2026년 02월 28일까지 | V1: 상호 | AA1: ㈜ 만두건설(건축)
V2: 현장명 | AA2: 1터널통합관리센터
A3: 2026-02 | V3: 책임자 | AA3: 민용기
A4: 번호 | C4: 성명 | E4: 일당 | G4: 출력현황
G5: {=_xlfn.LET( _xlpm.y, LEFT($A$3,4), _xlpm.m, RIGHT($A$3,2), _xlpm.d, _xlfn.SEQUENCE(1,31,1,1), _xlpm.date, DATE(_xlpm.y, _xlpm.m, _xlpm.d), IF(_xlpm.d<=DAY(EOMONTH(DATE(_xlpm.y,_xlpm.m,1),0)), _xlpm.date, "") )} -> 46054 | H5: 46055 | I5: 46056 | J5: 46057 | K5: 46058 | L5: 46059 | M5: 46060 | N5: 46061 | O5: 46062 | P5: 46063 | Q5: 46064 | R5: 46065 | S5: 46066 | T5: 46067 | U5: 46068 | V5: 46069 | W5: 46070 | X5: 46071 | Y5: 46072 | Z5: 46073 | AA5: 46074 | AB5: 46075 | AC5: 46076 | AD5: 46077 | AE5: 46078 | AF5: 46079 | AG5: 46080 | AH5: 46081 | AL5: 공수 | AN5: 총일수
A6: =ROW()-5 -> 1 | C6: 김철수 | AL6: =IF(SUM(G6:AK6)>0,SUM(G6:AK6),"") | AN6: =IF(COUNTA(G6:AK6)>0,COUNTA(G6:AJ6),"")
A7: =ROW()-5 -> 2 | C7: 이영휘 | AL7: =IF(SUM(G7:AK7)>0,SUM(G7:AK7),"") | AN7: =IF(COUNTA(G7:AK7)>0,COUNTA(G7:AJ7),"")
A8: =ROW()-5 -> 3 | C8: 박민수 | AL8: =IF(SUM(G8:AK8)>0,SUM(G8:AK8),"") | AN8: =IF(COUNTA(G8:AK8)>0,COUNTA(G8:AJ8),"")
A9: =ROW()-5 -> 4 | C9: 최지훈 | AL9: =IF(SUM(G9:AK9)>0,SUM(G9:AK9),"") | AN9: =IF(COUNTA(G9:AK9)>0,COUNTA(G9:AJ9),"")
A10: =ROW()-5 -> 5 | C10: 정수진 | AL10: =IF(SUM(G10:AK10)>0,SUM(G10:AK10),"") | AN10: =IF(COUNTA(G10:AK10)>0,COUNTA(G10:AJ10),"")
A11: =ROW()-5 -> 6 | C11: 이준호 | AL11: =IF(SUM(G11:AK11)>0,SUM(G11:AK11),"") | AN11: =IF(COUNTA(G11:AK11)>0,COUNTA(G11:AJ11),"")
A12: =ROW()-5 -> 7 | C12: 한지민 | AL12: =IF(SUM(G12:AK12)>0,SUM(G12:AK12),"") | AN12: =IF(COUNTA(G12:AK12)>0,COUNTA(G12:AJ12),"")
A13: =ROW()-5 -> 8 | C13: 오세훈 | G13: 1 | H13: 1 | I13: 1 | J13: 1 | K13: 1 | L13: 1 | M13: 1 | N13: 1 | O13: 1 | P13: 1 | Q13: 1 | R13: 1 | S13: 1 | T13: 1 | U13: 1 | V13: 1 | W13: 1 | X13: 1 | Y13: 1 | Z13: 1 | AA13: 1 | AB13: 1 | AC13: 1 | AD13: 1 | AE13: 1 | AF13: 1 | AG13: 1 | AH13: 1 | AL13: =IF(SUM(G13:AK13)>0,SUM(G13:AK13),"") -> 28 | AN13: =IF(COUNTA(G13:AK13)>0,COUNTA(G13:AJ13),"") -> 28
A14: =ROW()-5 -> 9 | C14: 장민재 | AL14: =IF(SUM(G14:AK14)>0,SUM(G14:AK14),"") | AN14: =IF(COUNTA(G14:AK14)>0,COUNTA(G14:AJ14),"")
A15: =ROW()-5 -> 10 | C15: 윤지아 | AL15: =IF(SUM(G15:AK15)>0,SUM(G15:AK15),"") | AN15: =IF(COUNTA(G15:AK15)>0,COUNTA(G15:AJ15),"")
A16: =ROW()-5 -> 11 | C16: 임동현 | AL16: =IF(SUM(G16:AK16)>0,SUM(G16:AK16),"") | AN16: =IF(COUNTA(G16:AK16)>0,COUNTA(G16:AJ16),"")
A17: =ROW()-5 -> 12 | C17: 심유진 | AL17: =IF(SUM(G17:AK17)>0,SUM(G17:AK17),"") | AN17: =IF(COUNTA(G17:AK17)>0,COUNTA(G17:AJ17),"")
A18: =ROW()-5 -> 13 | C18: 조현우 | AL18: =IF(SUM(G18:AK18)>0,SUM(G18:AK18),"") | AN18: =IF(COUNTA(G18:AK18)>0,COUNTA(G18:AJ18),"")
A19: =ROW()-5 -> 14 | C19: 서지은 | AL19: =IF(SUM(G19:AK19)>0,SUM(G19:AK19),"") | AN19: =IF(COUNTA(G19:AK19)>0,COUNTA(G19:AJ19),"")
A20: =ROW()-5 -> 15 | C20: 백승민 | AL20: =IF(SUM(G20:AK20)>0,SUM(G20:AK20),"") | AN20: =IF(COUNTA(G20:AK20)>0,COUNTA(G20:AJ20),"")
A21: =ROW()-5 -> 16 | C21: 강다연 | AL21: =IF(SUM(G21:AK21)>0,SUM(G21:AK21),"") | AN21: =IF(COUNTA(G21:AK21)>0,COUNTA(G21:AJ21),"")
A22: =ROW()-5 -> 17 | C22: 문지호 | AL22: =IF(SUM(G22:AK22)>0,SUM(G22:AK22),"") | AN22: =IF(COUNTA(G22:AK22)>0,COUNTA(G22:AJ22),"")
A23: =ROW()-5 -> 18 | AL23: =IF(SUM(G23:AK23)>0,SUM(G23:AK23),"") | AN23: =IF(COUNTA(G23:AK23)>0,COUNTA(G23:AJ23),"")
A24: =ROW()-5 -> 19 | AL24: =IF(SUM(G24:AK24)>0,SUM(G24:AK24),"") | AN24: =IF(COUNTA(G24:AK24)>0,COUNTA(G24:AJ24),"")
A25: =ROW()-5 -> 20 | AL25: =IF(SUM(G25:AK25)>0,SUM(G25:AK25),"") | AN25: =IF(COUNTA(G25:AK25)>0,COUNTA(G25:AJ25),"")
A26: =ROW()-5 -> 21 | AL26: =IF(SUM(G26:AK26)>0,SUM(G26:AK26),"") | AN26: =IF(COUNTA(G26:AK26)>0,COUNTA(G26:AJ26),"")
A27: =ROW()-5 -> 22 | AL27: =IF(SUM(G27:AK27)>0,SUM(G27:AK27),"") | AN27: =IF(COUNTA(G27:AK27)>0,COUNTA(G27:AJ27),"")
A28: =ROW()-5 -> 23 | AL28: =IF(SUM(G28:AK28)>0,SUM(G28:AK28),"") | AN28: =IF(COUNTA(G28:AK28)>0,COUNTA(G28:AJ28),"")
A29: =ROW()-5 -> 24 | AL29: =IF(SUM(G29:AK29)>0,SUM(G29:AK29),"") | AN29: =IF(COUNTA(G29:AK29)>0,COUNTA(G29:AJ29),"")
A30: =ROW()-5 -> 25 | AL30: =IF(SUM(G30:AK30)>0,SUM(G30:AK30),"") | AN30: =IF(COUNTA(G30:AK30)>0,COUNTA(G30:AJ30),"")
A31: 합계 | G31: =IF(SUM(G6:G30)>0,SUM(G6:G30),"") -> 1 | H31: =IF(SUM(H6:H30)>0,SUM(H6:H30),"") -> 1 | I31: =IF(SUM(I6:I30)>0,SUM(I6:I30),"") -> 1 | J31: =IF(SUM(J6:J30)>0,SUM(J6:J30),"") -> 1 | K31: =IF(SUM(K6:K30)>0,SUM(K6:K30),"") -> 1 | L31: =IF(SUM(L6:L30)>0,SUM(L6:L30),"") -> 1 | M31: =IF(SUM(M6:M30)>0,SUM(M6:M30),"") -> 1 | N31: =IF(SUM(N6:N30)>0,SUM(N6:N30),"") -> 1 | ... AK31: =IF(SUM(AK6:AK30)>0,SUM(AK6:AK30),"") | AL31: =SUM(AL6:AM30) -> 28 | AN31: =SUM(AN6:AO30) -> 28

Sheet 비고2
A1: 일용노무비지급명세서 | H1: 기간 | K1: =TEXT(DATE(LEFT(A3,4),RIGHT(A3,2),1),"yyyy""년"" mm""월"" dd""일""") & "부터" & CHAR(10) & TEXT(EOMONTH(DATE(LEFT(A3,4),RIGHT(A3,2),1),0),"yyyy""년"" mm""월"" dd""일""") & "까지" -> 2026년 02월 01일부터 2026년 02월 28일까지 | V1: 상호 | AA1: ㈜ 만두건설(건축)
V2: 현장명 | AA2: 1터널통합관리센터
A3: 2026-02 | V3: 책임자 | AA3: 민용기
A4: 번호 | C4: 성명 | E4: 일당 | G4: 출력현황
G5: {=_xlfn.LET( _xlpm.y, LEFT($A$3,4), _xlpm.m, RIGHT($A$3,2), _xlpm.d, _xlfn.SEQUENCE(1,31,1,1), _xlpm.date, DATE(_xlpm.y, _xlpm.m, _xlpm.d), IF(_xlpm.d<=DAY(EOMONTH(DATE(_xlpm.y,_xlpm.m,1),0)), _xlpm.date, "") )} -> 46054 | H5: 46055 | I5: 46056 | J5: 46057 | K5: 46058 | L5: 46059 | M5: 46060 | N5: 46061 | O5: 46062 | P5: 46063 | Q5: 46064 | R5: 46065 | S5: 46066 | T5: 46067 | U5: 46068 | V5: 46069 | W5: 46070 | X5: 46071 | Y5: 46072 | Z5: 46073 | AA5: 46074 | AB5: 46075 | AC5: 46076 | AD5: 46077 | AE5: 46078 | AF5: 46079 | AG5: 46080 | AH5: 46081 | AL5: 공수 | AN5: 총일수
A6: =ROW()-5 -> 1 | C6: 김철수 | AL6: =IF(SUM(G6:AK6)>0,SUM(G6:AK6),"") | AN6: =IF(COUNTA(G6:AK6)>0,COUNTA(G6:AJ6),"")
A7: =ROW()-5 -> 2 | C7: 이영휘 | AL7: =IF(SUM(G7:AK7)>0,SUM(G7:AK7),"") | AN7: =IF(COUNTA(G7:AK7)>0,COUNTA(G7:AJ7),"")
A8: =ROW()-5 -> 3 | C8: 박민수 | AL8: =IF(SUM(G8:AK8)>0,SUM(G8:AK8),"") | AN8: =IF(COUNTA(G8:AK8)>0,COUNTA(G8:AJ8),"")
A9: =ROW()-5 -> 4 | C9: 최지훈 | AL9: =IF(SUM(G9:AK9)>0,SUM(G9:AK9),"") | AN9: =IF(COUNTA(G9:AK9)>0,COUNTA(G9:AJ9),"")
A10: =ROW()-5 -> 5 | C10: 정수진 | AL10: =IF(SUM(G10:AK10)>0,SUM(G10:AK10),"") | AN10: =IF(COUNTA(G10:AK10)>0,COUNTA(G10:AJ10),"")
A11: =ROW()-5 -> 6 | C11: 이준호 | AL11: =IF(SUM(G11:AK11)>0,SUM(G11:AK11),"") | AN11: =IF(COUNTA(G11:AK11)>0,COUNTA(G11:AJ11),"")
A12: =ROW()-5 -> 7 | C12: 한지민 | AL12: =IF(SUM(G12:AK12)>0,SUM(G12:AK12),"") | AN12: =IF(COUNTA(G12:AK12)>0,COUNTA(G12:AJ12),"")
A13: =ROW()-5 -> 8 | C13: 오세훈 | AL13: =IF(SUM(G13:AK13)>0,SUM(G13:AK13),"") | AN13: =IF(COUNTA(G13:AK13)>0,COUNTA(G13:AJ13),"")
A14: =ROW()-5 -> 9 | C14: 장민재 | AL14: =IF(SUM(G14:AK14)>0,SUM(G14:AK14),"") | AN14: =IF(COUNTA(G14:AK14)>0,COUNTA(G14:AJ14),"")
A15: =ROW()-5 -> 10 | C15: 윤지아 | AL15: =IF(SUM(G15:AK15)>0,SUM(G15:AK15),"") | AN15: =IF(COUNTA(G15:AK15)>0,COUNTA(G15:AJ15),"")
A16: =ROW()-5 -> 11 | C16: 임동현 | AL16: =IF(SUM(G16:AK16)>0,SUM(G16:AK16),"") | AN16: =IF(COUNTA(G16:AK16)>0,COUNTA(G16:AJ16),"")
A17: =ROW()-5 -> 12 | C17: 심유진 | AL17: =IF(SUM(G17:AK17)>0,SUM(G17:AK17),"") | AN17: =IF(COUNTA(G17:AK17)>0,COUNTA(G17:AJ17),"")
A18: =ROW()-5 -> 13 | C18: 조현우 | G18: 1 | H18: 1 | I18: 1 | J18: 1 | K18: 1 | L18: 1 | M18: 1 | N18: 1 | O18: 1 | P18: 1 | Q18: 1 | R18: 1 | S18: 1 | T18: 1 | U18: 1 | V18: 1 | W18: 1 | X18: 1 | Y18: 1 | Z18: 1 | AA18: 1 | AB18: 1 | AC18: 1 | AD18: 1 | AE18: 1 | AF18: 1 | AG18: 1 | AH18: 1 | AI18: 1 | AJ18: 1 | AK18: 1 | AL18: =IF(SUM(G18:AK18)>0,SUM(G18:AK18),"") -> 31 | AN18: =IF(COUNTA(G18:AK18)>0,COUNTA(G18:AJ18),"") -> 30
A19: =ROW()-5 -> 14 | C19: 서지은 | AL19: =IF(SUM(G19:AK19)>0,SUM(G19:AK19),"") | AN19: =IF(COUNTA(G19:AK19)>0,COUNTA(G19:AJ19),"")
A20: =ROW()-5 -> 15 | C20: 백승민 | AL20: =IF(SUM(G20:AK20)>0,SUM(G20:AK20),"") | AN20: =IF(COUNTA(G20:AK20)>0,COUNTA(G20:AJ20),"")
A21: =ROW()-5 -> 16 | C21: 강다연 | AL21: =IF(SUM(G21:AK21)>0,SUM(G21:AK21),"") | AN21: =IF(COUNTA(G21:AK21)>0,COUNTA(G21:AJ21),"")
A22: =ROW()-5 -> 17 | C22: 문지호 | AL22: =IF(SUM(G22:AK22)>0,SUM(G22:AK22),"") | AN22: =IF(COUNTA(G22:AK22)>0,COUNTA(G22:AJ22),"")
A23: =ROW()-5 -> 18 | AL23: =IF(SUM(G23:AK23)>0,SUM(G23:AK23),"") | AN23: =IF(COUNTA(G23:AK23)>0,COUNTA(G23:AJ23),"")
A24: =ROW()-5 -> 19 | AL24: =IF(SUM(G24:AK24)>0,SUM(G24:AK24),"") | AN24: =IF(COUNTA(G24:AK24)>0,COUNTA(G24:AJ24),"")
A25: =ROW()-5 -> 20 | AL25: =IF(SUM(G25:AK25)>0,SUM(G25:AK25),"") | AN25: =IF(COUNTA(G25:AK25)>0,COUNTA(G25:AJ25),"")
A26: =ROW()-5 -> 21 | AL26: =IF(SUM(G26:AK26)>0,SUM(G26:AK26),"") | AN26: =IF(COUNTA(G26:AK26)>0,COUNTA(G26:AJ26),"")
A27: =ROW()-5 -> 22 | AL27: =IF(SUM(G27:AK27)>0,SUM(G27:AK27),"") | AN27: =IF(COUNTA(G27:AK27)>0,COUNTA(G27:AJ27),"")
A28: =ROW()-5 -> 23 | AL28: =IF(SUM(G28:AK28)>0,SUM(G28:AK28),"") | AN28: =IF(COUNTA(G28:AK28)>0,COUNTA(G28:AJ28),"")
A29: =ROW()-5 -> 24 | AL29: =IF(SUM(G29:AK29)>0,SUM(G29:AK29),"") | AN29: =IF(COUNTA(G29:AK29)>0,COUNTA(G29:AJ29),"")
A30: =ROW()-5 -> 25 | AL30: =IF(SUM(G30:AK30)>0,SUM(G30:AK30),"") | AN30: =IF(COUNTA(G30:AK30)>0,COUNTA(G30:AJ30),"")
A31: 합계 | G31: =IF(SUM(G6:G30)>0,SUM(G6:G30),"") -> 1 | H31: =IF(SUM(H6:H30)>0,SUM(H6:H30),"") -> 1 | I31: =IF(SUM(I6:I30)>0,SUM(I6:I30),"") -> 1 | J31: =IF(SUM(J6:J30)>0,SUM(J6:J30),"") -> 1 | K31: =IF(SUM(K6:K30)>0,SUM(K6:K30),"") -> 1 | L31: =IF(SUM(L6:L30)>0,SUM(L6:L30),"") -> 1 | M31: =IF(SUM(M6:M30)>0,SUM(M6:M30),"") -> 1 | N31: =IF(SUM(N6:N30)>0,SUM(N6:N30),"") -> 1 | ... AK31: =IF(SUM(AK6:AK30)>0,SUM(AK6:AK30),"") -> 1 | AL31: =SUM(AL6:AM30) -> 31 | AN31: =SUM(AN6:AO30) -> 30

Sheet 출력관리
A1: 일용노무비지급명세서 | H1: 기간 | K1: =TEXT(DATE(LEFT(A3,4),RIGHT(A3,2),1),"yyyy""년"" mm""월"" dd""일""") & "부터" & CHAR(10) & TEXT(EOMONTH(DATE(LEFT(A3,4),RIGHT(A3,2),1),0),"yyyy""년"" mm""월"" dd""일""") & "까지" -> 2026년 02월 01일부터 2026년 02월 28일까지 | V1: 상호 | AA1: ㈜ 만두건설(건축)
V2: 현장명 | AA2: 1터널통합관리센터
A3: 2026-02 | V3: 책임자 | AA3: 민용기
A4: 번호 | C4: 성명 | E4: 일당 | G4: 출력현황 | AP4: 만두건설 | AR4: 만두토목 | AT4: 홍천서석 | AV4: 사창리 | AX4: 대원건설 | AZ4: 정윤일 | BB4: 비고1 | BD4: 비고2
G5: {=_xlfn.LET( _xlpm.y, LEFT($A$3,4), _xlpm.m, RIGHT($A$3,2), _xlpm.d, _xlfn.SEQUENCE(1,31,1,1), _xlpm.date, DATE(_xlpm.y, _xlpm.m, _xlpm.d), IF(_xlpm.d<=DAY(EOMONTH(DATE(_xlpm.y,_xlpm.m,1),0)), _xlpm.date, "") )} -> 46054 | H5: 46055 | I5: 46056 | J5: 46057 | K5: 46058 | L5: 46059 | M5: 46060 | N5: 46061 | O5: 46062 | P5: 46063 | Q5: 46064 | R5: 46065 | S5: 46066 | T5: 46067 | U5: 46068 | V5: 46069 | W5: 46070 | X5: 46071 | Y5: 46072 | Z5: 46073 | AA5: 46074 | AB5: 46075 | AC5: 46076 | AD5: 46077 | AE5: 46078 | AF5: 46079 | AG5: 46080 | AH5: 46081 | AL5: 공수 | AN5: 총일수
A6: =ROW()-5 -> 1 | C6: 김철수 | G6: =IF(만두건설!G6+만두토목!G6+홍천서석!G6+사창리!G6+대원건설!G6+정윤일!G6+비고1!G6+비고2!G6>0,만두건설!G6+만두토목!G6+홍천서석!G6+사창리!G6+대원건설!G6+정윤일!G6+비고1!G6+비고2!G6,"") -> 1 | H6: =IF(만두건설!H6+만두토목!H6+홍천서석!H6+사창리!H6+대원건설!H6+정윤일!H6+비고1!H6+비고2!H6>0,만두건설!H6+만두토목!H6+홍천서석!H6+사창리!H6+대원건설!H6+정윤일!H6+비고1!H6+비고2!H6,"") -> 1 | I6: =IF(만두건설!I6+만두토목!I6+홍천서석!I6+사창리!I6+대원건설!I6+정윤일!I6+비고1!I6+비고2!I6>0,만두건설!I6+만두토목!I6+홍천서석!I6+사창리!I6+대원건설!I6+정윤일!I6+비고1!I6+비고2!I6,"") -> 1 | J6: =IF(만두건설!J6+만두토목!J6+홍천서석!J6+사창리!J6+대원건설!J6+정윤일!J6+비고1!J6+비고2!J6>0,만두건설!J6+만두토목!J6+홍천서석!J6+사창리!J6+대원건설!J6+정윤일!J6+비고1!J6+비고2!J6,"") -> 1 | K6: =IF(만두건설!K6+만두토목!K6+홍천서석!K6+사창리!K6+대원건설!K6+정윤일!K6+비고1!K6+비고2!K6>0,만두건설!K6+만두토목!K6+홍천서석!K6+사창리!K6+대원건설!K6+정윤일!K6+비고1!K6+비고2!K6,"") -> 1 | L6: =IF(만두건설!L6+만두토목!L6+홍천서석!L6+사창리!L6+대원건설!L6+정윤일!L6+비고1!L6+비고2!L6>0,만두건설!L6+만두토목!L6+홍천서석!L6+사창리!L6+대원건설!L6+정윤일!L6+비고1!L6+비고2!L6,"") -> 1 | M6: =IF(만두건설!M6+만두토목!M6+홍천서석!M6+사창리!M6+대원건설!M6+정윤일!M6+비고1!M6+비고2!M6>0,만두건설!M6+만두토목!M6+홍천서석!M6+사창리!M6+대원건설!M6+정윤일!M6+비고1!M6+비고2!M6,"") -> 1 | N6: =IF(만두건설!N6+만두토목!N6+홍천서석!N6+사창리!N6+대원건설!N6+정윤일!N6+비고1!N6+비고2!N6>0,만두건설!N6+만두토목!N6+홍천서석!N6+사창리!N6+대원건설!N6+정윤일!N6+비고1!N6+비고2!N6,"") -> 1 | ... AK6: =IF(만두건설!AK6+만두토목!AK6+홍천서석!AK6+사창리!AK6+대원건설!AK6+정윤일!AK6+비고1!AK6+비고2!AK6>0,만두건설!AK6+만두토목!AK6+홍천서석!AK6+사창리!AK6+대원건설!AK6+정윤일!AK6+비고1!AK6+비고2!AK6,"") | AL6: =IF(SUM(G6:AK6)>0,SUM(G6:AK6),"") -> 28 | AN6: =(COUNT(G6:AK6)) -> 28 | AP6: =IF(만두건설!AL6>0,만두건설!AL6,"") -> 28 | AR6: =IF(만두토목!AL6>0,만두토목!AL6,"") | AT6: =IF(홍천서석!AL6>0,홍천서석!AL6,"") | AV6: =IF(사창리!AL6>0,사창리!AL6,"") | AX6: =IF(대원건설!AL6>0,대원건설!AL6,"") | AZ6: =IF(정윤일!AL6>0,정윤일!AL6,"") | BB6: =IF(비고1!AL6>0,비고1!AL6,"") | BD6: =IF(비고2!AL6>0,비고2!AL6,"")
A7: =ROW()-5 -> 2 | C7: 이영휘 | G7: =IF(만두건설!G7+만두토목!G7+홍천서석!G7+사창리!G7+대원건설!G7+정윤일!G7+비고1!G7+비고2!G7>0,만두건설!G7+만두토목!G7+홍천서석!G7+사창리!G7+대원건설!G7+정윤일!G7+비고1!G7+비고2!G7,"") -> 1 | H7: =IF(만두건설!H7+만두토목!H7+홍천서석!H7+사창리!H7+대원건설!H7+정윤일!H7+비고1!H7+비고2!H7>0,만두건설!H7+만두토목!H7+홍천서석!H7+사창리!H7+대원건설!H7+정윤일!H7+비고1!H7+비고2!H7,"") -> 1 | I7: =IF(만두건설!I7+만두토목!I7+홍천서석!I7+사창리!I7+대원건설!I7+정윤일!I7+비고1!I7+비고2!I7>0,만두건설!I7+만두토목!I7+홍천서석!I7+사창리!I7+대원건설!I7+정윤일!I7+비고1!I7+비고2!I7,"") -> 1 | J7: =IF(만두건설!J7+만두토목!J7+홍천서석!J7+사창리!J7+대원건설!J7+정윤일!J7+비고1!J7+비고2!J7>0,만두건설!J7+만두토목!J7+홍천서석!J7+사창리!J7+대원건설!J7+정윤일!J7+비고1!J7+비고2!J7,"") -> 1 | K7: =IF(만두건설!K7+만두토목!K7+홍천서석!K7+사창리!K7+대원건설!K7+정윤일!K7+비고1!K7+비고2!K7>0,만두건설!K7+만두토목!K7+홍천서석!K7+사창리!K7+대원건설!K7+정윤일!K7+비고1!K7+비고2!K7,"") -> 1 | L7: =IF(만두건설!L7+만두토목!L7+홍천서석!L7+사창리!L7+대원건설!L7+정윤일!L7+비고1!L7+비고2!L7>0,만두건설!L7+만두토목!L7+홍천서석!L7+사창리!L7+대원건설!L7+정윤일!L7+비고1!L7+비고2!L7,"") -> 1 | M7: =IF(만두건설!M7+만두토목!M7+홍천서석!M7+사창리!M7+대원건설!M7+정윤일!M7+비고1!M7+비고2!M7>0,만두건설!M7+만두토목!M7+홍천서석!M7+사창리!M7+대원건설!M7+정윤일!M7+비고1!M7+비고2!M7,"") -> 1 | N7: =IF(만두건설!N7+만두토목!N7+홍천서석!N7+사창리!N7+대원건설!N7+정윤일!N7+비고1!N7+비고2!N7>0,만두건설!N7+만두토목!N7+홍천서석!N7+사창리!N7+대원건설!N7+정윤일!N7+비고1!N7+비고2!N7,"") -> 1 | ... AK7: =IF(만두건설!AK7+만두토목!AK7+홍천서석!AK7+사창리!AK7+대원건설!AK7+정윤일!AK7+비고1!AK7+비고2!AK7>0,만두건설!AK7+만두토목!AK7+홍천서석!AK7+사창리!AK7+대원건설!AK7+정윤일!AK7+비고1!AK7+비고2!AK7,"") | AL7: =IF(SUM(G7:AK7)>0,SUM(G7:AK7),"") -> 28 | AN7: =(COUNT(G7:AK7)) -> 28 | AP7: =IF(만두건설!AL7>0,만두건설!AL7,"") | AR7: =IF(만두토목!AL7>0,만두토목!AL7,"") -> 28 | AT7: =IF(홍천서석!AL7>0,홍천서석!AL7,"") | AV7: =IF(사창리!AL7>0,사창리!AL7,"") | AX7: =IF(대원건설!AL7>0,대원건설!AL7,"") | AZ7: =IF(정윤일!AL7>0,정윤일!AL7,"") | BB7: =IF(비고1!AL7>0,비고1!AL7,"") | BD7: =IF(비고2!AL7>0,비고2!AL7,"")
A8: =ROW()-5 -> 3 | C8: 박민수 | G8: =IF(만두건설!G8+만두토목!G8+홍천서석!G8+사창리!G8+대원건설!G8+정윤일!G8+비고1!G8+비고2!G8>0,만두건설!G8+만두토목!G8+홍천서석!G8+사창리!G8+대원건설!G8+정윤일!G8+비고1!G8+비고2!G8,"") -> 1 | H8: =IF(만두건설!H8+만두토목!H8+홍천서석!H8+사창리!H8+대원건설!H8+정윤일!H8+비고1!H8+비고2!H8>0,만두건설!H8+만두토목!H8+홍천서석!H8+사창리!H8+대원건설!H8+정윤일!H8+비고1!H8+비고2!H8,"") -> 1 | I8: =IF(만두건설!I8+만두토목!I8+홍천서석!I8+사창리!I8+대원건설!I8+정윤일!I8+비고1!I8+비고2!I8>0,만두건설!I8+만두토목!I8+홍천서석!I8+사창리!I8+대원건설!I8+정윤일!I8+비고1!I8+비고2!I8,"") -> 1 | J8: =IF(만두건설!J8+만두토목!J8+홍천서석!J8+사창리!J8+대원건설!J8+정윤일!J8+비고1!J8+비고2!J8>0,만두건설!J8+만두토목!J8+홍천서석!J8+사창리!J8+대원건설!J8+정윤일!J8+비고1!J8+비고2!J8,"") -> 1 | K8: =IF(만두건설!K8+만두토목!K8+홍천서석!K8+사창리!K8+대원건설!K8+정윤일!K8+비고1!K8+비고2!K8>0,만두건설!K8+만두토목!K8+홍천서석!K8+사창리!K8+대원건설!K8+정윤일!K8+비고1!K8+비고2!K8,"") -> 1 | L8: =IF(만두건설!L8+만두토목!L8+홍천서석!L8+사창리!L8+대원건설!L8+정윤일!L8+비고1!L8+비고2!L8>0,만두건설!L8+만두토목!L8+홍천서석!L8+사창리!L8+대원건설!L8+정윤일!L8+비고1!L8+비고2!L8,"") -> 1 | M8: =IF(만두건설!M8+만두토목!M8+홍천서석!M8+사창리!M8+대원건설!M8+정윤일!M8+비고1!M8+비고2!M8>0,만두건설!M8+만두토목!M8+홍천서석!M8+사창리!M8+대원건설!M8+정윤일!M8+비고1!M8+비고2!M8,"") -> 1 | N8: =IF(만두건설!N8+만두토목!N8+홍천서석!N8+사창리!N8+대원건설!N8+정윤일!N8+비고1!N8+비고2!N8>0,만두건설!N8+만두토목!N8+홍천서석!N8+사창리!N8+대원건설!N8+정윤일!N8+비고1!N8+비고2!N8,"") -> 1 | ... AK8: =IF(만두건설!AK8+만두토목!AK8+홍천서석!AK8+사창리!AK8+대원건설!AK8+정윤일!AK8+비고1!AK8+비고2!AK8>0,만두건설!AK8+만두토목!AK8+홍천서석!AK8+사창리!AK8+대원건설!AK8+정윤일!AK8+비고1!AK8+비고2!AK8,"") | AL8: =IF(SUM(G8:AK8)>0,SUM(G8:AK8),"") -> 28 | AN8: =(COUNT(G8:AK8)) -> 28 | AP8: =IF(만두건설!AL8>0,만두건설!AL8,"") | AR8: =IF(만두토목!AL8>0,만두토목!AL8,"") | AT8: =IF(홍천서석!AL8>0,홍천서석!AL8,"") -> 28 | AV8: =IF(사창리!AL8>0,사창리!AL8,"") | AX8: =IF(대원건설!AL8>0,대원건설!AL8,"") | AZ8: =IF(정윤일!AL8>0,정윤일!AL8,"") | BB8: =IF(비고1!AL8>0,비고1!AL8,"") | BD8: =IF(비고2!AL8>0,비고2!AL8,"")
A9: =ROW()-5 -> 4 | C9: 최지훈 | G9: =IF(만두건설!G9+만두토목!G9+홍천서석!G9+사창리!G9+대원건설!G9+정윤일!G9+비고1!G9+비고2!G9>0,만두건설!G9+만두토목!G9+홍천서석!G9+사창리!G9+대원건설!G9+정윤일!G9+비고1!G9+비고2!G9,"") -> 1 | H9: =IF(만두건설!H9+만두토목!H9+홍천서석!H9+사창리!H9+대원건설!H9+정윤일!H9+비고1!H9+비고2!H9>0,만두건설!H9+만두토목!H9+홍천서석!H9+사창리!H9+대원건설!H9+정윤일!H9+비고1!H9+비고2!H9,"") -> 1 | I9: =IF(만두건설!I9+만두토목!I9+홍천서석!I9+사창리!I9+대원건설!I9+정윤일!I9+비고1!I9+비고2!I9>0,만두건설!I9+만두토목!I9+홍천서석!I9+사창리!I9+대원건설!I9+정윤일!I9+비고1!I9+비고2!I9,"") -> 1 | J9: =IF(만두건설!J9+만두토목!J9+홍천서석!J9+사창리!J9+대원건설!J9+정윤일!J9+비고1!J9+비고2!J9>0,만두건설!J9+만두토목!J9+홍천서석!J9+사창리!J9+대원건설!J9+정윤일!J9+비고1!J9+비고2!J9,"") -> 1 | K9: =IF(만두건설!K9+만두토목!K9+홍천서석!K9+사창리!K9+대원건설!K9+정윤일!K9+비고1!K9+비고2!K9>0,만두건설!K9+만두토목!K9+홍천서석!K9+사창리!K9+대원건설!K9+정윤일!K9+비고1!K9+비고2!K9,"") -> 1 | L9: =IF(만두건설!L9+만두토목!L9+홍천서석!L9+사창리!L9+대원건설!L9+정윤일!L9+비고1!L9+비고2!L9>0,만두건설!L9+만두토목!L9+홍천서석!L9+사창리!L9+대원건설!L9+정윤일!L9+비고1!L9+비고2!L9,"") -> 1 | M9: =IF(만두건설!M9+만두토목!M9+홍천서석!M9+사창리!M9+대원건설!M9+정윤일!M9+비고1!M9+비고2!M9>0,만두건설!M9+만두토목!M9+홍천서석!M9+사창리!M9+대원건설!M9+정윤일!M9+비고1!M9+비고2!M9,"") -> 1 | N9: =IF(만두건설!N9+만두토목!N9+홍천서석!N9+사창리!N9+대원건설!N9+정윤일!N9+비고1!N9+비고2!N9>0,만두건설!N9+만두토목!N9+홍천서석!N9+사창리!N9+대원건설!N9+정윤일!N9+비고1!N9+비고2!N9,"") -> 1 | ... AK9: =IF(만두건설!AK9+만두토목!AK9+홍천서석!AK9+사창리!AK9+대원건설!AK9+정윤일!AK9+비고1!AK9+비고2!AK9>0,만두건설!AK9+만두토목!AK9+홍천서석!AK9+사창리!AK9+대원건설!AK9+정윤일!AK9+비고1!AK9+비고2!AK9,"") | AL9: =IF(SUM(G9:AK9)>0,SUM(G9:AK9),"") -> 28 | AN9: =(COUNT(G9:AK9)) -> 28 | AP9: =IF(만두건설!AL9>0,만두건설!AL9,"") | AR9: =IF(만두토목!AL9>0,만두토목!AL9,"") | AT9: =IF(홍천서석!AL9>0,홍천서석!AL9,"") | AV9: =IF(사창리!AL9>0,사창리!AL9,"") -> 28 | AX9: =IF(대원건설!AL9>0,대원건설!AL9,"") | AZ9: =IF(정윤일!AL9>0,정윤일!AL9,"") | BB9: =IF(비고1!AL9>0,비고1!AL9,"") | BD9: =IF(비고2!AL9>0,비고2!AL9,"")
A10: =ROW()-5 -> 5 | C10: 정수진 | G10: =IF(만두건설!G10+만두토목!G10+홍천서석!G10+사창리!G10+대원건설!G10+정윤일!G10+비고1!G10+비고2!G10>0,만두건설!G10+만두토목!G10+홍천서석!G10+사창리!G10+대원건설!G10+정윤일!G10+비고1!G10+비고2!G10,"") -> 1 | H10: =IF(만두건설!H10+만두토목!H10+홍천서석!H10+사창리!H10+대원건설!H10+정윤일!H10+비고1!H10+비고2!H10>0,만두건설!H10+만두토목!H10+홍천서석!H10+사창리!H10+대원건설!H10+정윤일!H10+비고1!H10+비고2!H10,"") -> 1 | I10: =IF(만두건설!I10+만두토목!I10+홍천서석!I10+사창리!I10+대원건설!I10+정윤일!I10+비고1!I10+비고2!I10>0,만두건설!I10+만두토목!I10+홍천서석!I10+사창리!I10+대원건설!I10+정윤일!I10+비고1!I10+비고2!I10,"") -> 1 | J10: =IF(만두건설!J10+만두토목!J10+홍천서석!J10+사창리!J10+대원건설!J10+정윤일!J10+비고1!J10+비고2!J10>0,만두건설!J10+만두토목!J10+홍천서석!J10+사창리!J10+대원건설!J10+정윤일!J10+비고1!J10+비고2!J10,"") -> 1 | K10: =IF(만두건설!K10+만두토목!K10+홍천서석!K10+사창리!K10+대원건설!K10+정윤일!K10+비고1!K10+비고2!K10>0,만두건설!K10+만두토목!K10+홍천서석!K10+사창리!K10+대원건설!K10+정윤일!K10+비고1!K10+비고2!K10,"") -> 1 | L10: =IF(만두건설!L10+만두토목!L10+홍천서석!L10+사창리!L10+대원건설!L10+정윤일!L10+비고1!L10+비고2!L10>0,만두건설!L10+만두토목!L10+홍천서석!L10+사창리!L10+대원건설!L10+정윤일!L10+비고1!L10+비고2!L10,"") -> 1 | M10: =IF(만두건설!M10+만두토목!M10+홍천서석!M10+사창리!M10+대원건설!M10+정윤일!M10+비고1!M10+비고2!M10>0,만두건설!M10+만두토목!M10+홍천서석!M10+사창리!M10+대원건설!M10+정윤일!M10+비고1!M10+비고2!M10,"") -> 1 | N10: =IF(만두건설!N10+만두토목!N10+홍천서석!N10+사창리!N10+대원건설!N10+정윤일!N10+비고1!N10+비고2!N10>0,만두건설!N10+만두토목!N10+홍천서석!N10+사창리!N10+대원건설!N10+정윤일!N10+비고1!N10+비고2!N10,"") -> 1 | ... AK10: =IF(만두건설!AK10+만두토목!AK10+홍천서석!AK10+사창리!AK10+대원건설!AK10+정윤일!AK10+비고1!AK10+비고2!AK10>0,만두건설!AK10+만두토목!AK10+홍천서석!AK10+사창리!AK10+대원건설!AK10+정윤일!AK10+비고1!AK10+비고2!AK10,"") | AL10: =IF(SUM(G10:AK10)>0,SUM(G10:AK10),"") -> 28 | AN10: =(COUNT(G10:AK10)) -> 28 | AP10: =IF(만두건설!AL10>0,만두건설!AL10,"") | AR10: =IF(만두토목!AL10>0,만두토목!AL10,"") | AT10: =IF(홍천서석!AL10>0,홍천서석!AL10,"") | AV10: =IF(사창리!AL10>0,사창리!AL10,"") | AX10: =IF(대원건설!AL10>0,대원건설!AL10,"") -> 28 | AZ10: =IF(정윤일!AL10>0,정윤일!AL10,"") | BB10: =IF(비고1!AL10>0,비고1!AL10,"") | BD10: =IF(비고2!AL10>0,비고2!AL10,"")
A11: =ROW()-5 -> 6 | C11: 이준호 | G11: =IF(만두건설!G11+만두토목!G11+홍천서석!G11+사창리!G11+대원건설!G11+정윤일!G11+비고1!G11+비고2!G11>0,만두건설!G11+만두토목!G11+홍천서석!G11+사창리!G11+대원건설!G11+정윤일!G11+비고1!G11+비고2!G11,"") -> 1 | H11: =IF(만두건설!H11+만두토목!H11+홍천서석!H11+사창리!H11+대원건설!H11+정윤일!H11+비고1!H11+비고2!H11>0,만두건설!H11+만두토목!H11+홍천서석!H11+사창리!H11+대원건설!H11+정윤일!H11+비고1!H11+비고2!H11,"") -> 1 | I11: =IF(만두건설!I11+만두토목!I11+홍천서석!I11+사창리!I11+대원건설!I11+정윤일!I11+비고1!I11+비고2!I11>0,만두건설!I11+만두토목!I11+홍천서석!I11+사창리!I11+대원건설!I11+정윤일!I11+비고1!I11+비고2!I11,"") -> 1 | J11: =IF(만두건설!J11+만두토목!J11+홍천서석!J11+사창리!J11+대원건설!J11+정윤일!J11+비고1!J11+비고2!J11>0,만두건설!J11+만두토목!J11+홍천서석!J11+사창리!J11+대원건설!J11+정윤일!J11+비고1!J11+비고2!J11,"") -> 1 | K11: =IF(만두건설!K11+만두토목!K11+홍천서석!K11+사창리!K11+대원건설!K11+정윤일!K11+비고1!K11+비고2!K11>0,만두건설!K11+만두토목!K11+홍천서석!K11+사창리!K11+대원건설!K11+정윤일!K11+비고1!K11+비고2!K11,"") -> 1 | L11: =IF(만두건설!L11+만두토목!L11+홍천서석!L11+사창리!L11+대원건설!L11+정윤일!L11+비고1!L11+비고2!L11>0,만두건설!L11+만두토목!L11+홍천서석!L11+사창리!L11+대원건설!L11+정윤일!L11+비고1!L11+비고2!L11,"") -> 1 | M11: =IF(만두건설!M11+만두토목!M11+홍천서석!M11+사창리!M11+대원건설!M11+정윤일!M11+비고1!M11+비고2!M11>0,만두건설!M11+만두토목!M11+홍천서석!M11+사창리!M11+대원건설!M11+정윤일!M11+비고1!M11+비고2!M11,"") -> 1 | N11: =IF(만두건설!N11+만두토목!N11+홍천서석!N11+사창리!N11+대원건설!N11+정윤일!N11+비고1!N11+비고2!N11>0,만두건설!N11+만두토목!N11+홍천서석!N11+사창리!N11+대원건설!N11+정윤일!N11+비고1!N11+비고2!N11,"") -> 1 | ... AK11: =IF(만두건설!AK11+만두토목!AK11+홍천서석!AK11+사창리!AK11+대원건설!AK11+정윤일!AK11+비고1!AK11+비고2!AK11>0,만두건설!AK11+만두토목!AK11+홍천서석!AK11+사창리!AK11+대원건설!AK11+정윤일!AK11+비고1!AK11+비고2!AK11,"") | AL11: =IF(SUM(G11:AK11)>0,SUM(G11:AK11),"") -> 28 | AN11: =(COUNT(G11:AK11)) -> 28 | AP11: =IF(만두건설!AL11>0,만두건설!AL11,"") | AR11: =IF(만두토목!AL11>0,만두토목!AL11,"") | AT11: =IF(홍천서석!AL11>0,홍천서석!AL11,"") | AV11: =IF(사창리!AL11>0,사창리!AL11,"") | AX11: =IF(대원건설!AL11>0,대원건설!AL11,"") | AZ11: =IF(정윤일!AL11>0,정윤일!AL11,"") -> 28 | BB11: =IF(비고1!AL11>0,비고1!AL11,"") | BD11: =IF(비고2!AL11>0,비고2!AL11,"")
A12: =ROW()-5 -> 7 | C12: 한지민 | G12: =IF(만두건설!G12+만두토목!G12+홍천서석!G12+사창리!G12+대원건설!G12+정윤일!G12+비고1!G12+비고2!G12>0,만두건설!G12+만두토목!G12+홍천서석!G12+사창리!G12+대원건설!G12+정윤일!G12+비고1!G12+비고2!G12,"") | H12: =IF(만두건설!H12+만두토목!H12+홍천서석!H12+사창리!H12+대원건설!H12+정윤일!H12+비고1!H12+비고2!H12>0,만두건설!H12+만두토목!H12+홍천서석!H12+사창리!H12+대원건설!H12+정윤일!H12+비고1!H12+비고2!H12,"") | I12: =IF(만두건설!I12+만두토목!I12+홍천서석!I12+사창리!I12+대원건설!I12+정윤일!I12+비고1!I12+비고2!I12>0,만두건설!I12+만두토목!I12+홍천서석!I12+사창리!I12+대원건설!I12+정윤일!I12+비고1!I12+비고2!I12,"") | J12: =IF(만두건설!J12+만두토목!J12+홍천서석!J12+사창리!J12+대원건설!J12+정윤일!J12+비고1!J12+비고2!J12>0,만두건설!J12+만두토목!J12+홍천서석!J12+사창리!J12+대원건설!J12+정윤일!J12+비고1!J12+비고2!J12,"") | K12: =IF(만두건설!K12+만두토목!K12+홍천서석!K12+사창리!K12+대원건설!K12+정윤일!K12+비고1!K12+비고2!K12>0,만두건설!K12+만두토목!K12+홍천서석!K12+사창리!K12+대원건설!K12+정윤일!K12+비고1!K12+비고2!K12,"") | L12: =IF(만두건설!L12+만두토목!L12+홍천서석!L12+사창리!L12+대원건설!L12+정윤일!L12+비고1!L12+비고2!L12>0,만두건설!L12+만두토목!L12+홍천서석!L12+사창리!L12+대원건설!L12+정윤일!L12+비고1!L12+비고2!L12,"") | M12: =IF(만두건설!M12+만두토목!M12+홍천서석!M12+사창리!M12+대원건설!M12+정윤일!M12+비고1!M12+비고2!M12>0,만두건설!M12+만두토목!M12+홍천서석!M12+사창리!M12+대원건설!M12+정윤일!M12+비고1!M12+비고2!M12,"") | N12: =IF(만두건설!N12+만두토목!N12+홍천서석!N12+사창리!N12+대원건설!N12+정윤일!N12+비고1!N12+비고2!N12>0,만두건설!N12+만두토목!N12+홍천서석!N12+사창리!N12+대원건설!N12+정윤일!N12+비고1!N12+비고2!N12,"") | ... AK12: =IF(만두건설!AK12+만두토목!AK12+홍천서석!AK12+사창리!AK12+대원건설!AK12+정윤일!AK12+비고1!AK12+비고2!AK12>0,만두건설!AK12+만두토목!AK12+홍천서석!AK12+사창리!AK12+대원건설!AK12+정윤일!AK12+비고1!AK12+비고2!AK12,"") | AL12: =IF(SUM(G12:AK12)>0,SUM(G12:AK12),"") | AN12: =(COUNT(G12:AK12)) -> 0 | AP12: =IF(만두건설!AL12>0,만두건설!AL12,"") | AR12: =IF(만두토목!AL12>0,만두토목!AL12,"") | AT12: =IF(홍천서석!AL12>0,홍천서석!AL12,"") | AV12: =IF(사창리!AL12>0,사창리!AL12,"") | AX12: =IF(대원건설!AL12>0,대원건설!AL12,"") | AZ12: =IF(정윤일!AL12>0,정윤일!AL12,"") | BB12: =IF(비고1!AL12>0,비고1!AL12,"") | BD12: =IF(비고2!AL12>0,비고2!AL12,"")
A13: =ROW()-5 -> 8 | C13: 오세훈 | G13: =IF(만두건설!G13+만두토목!G13+홍천서석!G13+사창리!G13+대원건설!G13+정윤일!G13+비고1!G13+비고2!G13>0,만두건설!G13+만두토목!G13+홍천서석!G13+사창리!G13+대원건설!G13+정윤일!G13+비고1!G13+비고2!G13,"") -> 1 | H13: =IF(만두건설!H13+만두토목!H13+홍천서석!H13+사창리!H13+대원건설!H13+정윤일!H13+비고1!H13+비고2!H13>0,만두건설!H13+만두토목!H13+홍천서석!H13+사창리!H13+대원건설!H13+정윤일!H13+비고1!H13+비고2!H13,"") -> 1 | I13: =IF(만두건설!I13+만두토목!I13+홍천서석!I13+사창리!I13+대원건설!I13+정윤일!I13+비고1!I13+비고2!I13>0,만두건설!I13+만두토목!I13+홍천서석!I13+사창리!I13+대원건설!I13+정윤일!I13+비고1!I13+비고2!I13,"") -> 1 | J13: =IF(만두건설!J13+만두토목!J13+홍천서석!J13+사창리!J13+대원건설!J13+정윤일!J13+비고1!J13+비고2!J13>0,만두건설!J13+만두토목!J13+홍천서석!J13+사창리!J13+대원건설!J13+정윤일!J13+비고1!J13+비고2!J13,"") -> 1 | K13: =IF(만두건설!K13+만두토목!K13+홍천서석!K13+사창리!K13+대원건설!K13+정윤일!K13+비고1!K13+비고2!K13>0,만두건설!K13+만두토목!K13+홍천서석!K13+사창리!K13+대원건설!K13+정윤일!K13+비고1!K13+비고2!K13,"") -> 1 | L13: =IF(만두건설!L13+만두토목!L13+홍천서석!L13+사창리!L13+대원건설!L13+정윤일!L13+비고1!L13+비고2!L13>0,만두건설!L13+만두토목!L13+홍천서석!L13+사창리!L13+대원건설!L13+정윤일!L13+비고1!L13+비고2!L13,"") -> 1 | M13: =IF(만두건설!M13+만두토목!M13+홍천서석!M13+사창리!M13+대원건설!M13+정윤일!M13+비고1!M13+비고2!M13>0,만두건설!M13+만두토목!M13+홍천서석!M13+사창리!M13+대원건설!M13+정윤일!M13+비고1!M13+비고2!M13,"") -> 1 | N13: =IF(만두건설!N13+만두토목!N13+홍천서석!N13+사창리!N13+대원건설!N13+정윤일!N13+비고1!N13+비고2!N13>0,만두건설!N13+만두토목!N13+홍천서석!N13+사창리!N13+대원건설!N13+정윤일!N13+비고1!N13+비고2!N13,"") -> 1 | ... AK13: =IF(만두건설!AK13+만두토목!AK13+홍천서석!AK13+사창리!AK13+대원건설!AK13+정윤일!AK13+비고1!AK13+비고2!AK13>0,만두건설!AK13+만두토목!AK13+홍천서석!AK13+사창리!AK13+대원건설!AK13+정윤일!AK13+비고1!AK13+비고2!AK13,"") | AL13: =IF(SUM(G13:AK13)>0,SUM(G13:AK13),"") -> 28 | AN13: =(COUNT(G13:AK13)) -> 28 | AP13: =IF(만두건설!AL13>0,만두건설!AL13,"") | AR13: =IF(만두토목!AL13>0,만두토목!AL13,"") | AT13: =IF(홍천서석!AL13>0,홍천서석!AL13,"") | AV13: =IF(사창리!AL13>0,사창리!AL13,"") | AX13: =IF(대원건설!AL13>0,대원건설!AL13,"") | AZ13: =IF(정윤일!AL13>0,정윤일!AL13,"") | BB13: =IF(비고1!AL13>0,비고1!AL13,"") -> 28 | BD13: =IF(비고2!AL13>0,비고2!AL13,"")
A14: =ROW()-5 -> 9 | C14: 장민재 | G14: =IF(만두건설!G14+만두토목!G14+홍천서석!G14+사창리!G14+대원건설!G14+정윤일!G14+비고1!G14+비고2!G14>0,만두건설!G14+만두토목!G14+홍천서석!G14+사창리!G14+대원건설!G14+정윤일!G14+비고1!G14+비고2!G14,"") | H14: =IF(만두건설!H14+만두토목!H14+홍천서석!H14+사창리!H14+대원건설!H14+정윤일!H14+비고1!H14+비고2!H14>0,만두건설!H14+만두토목!H14+홍천서석!H14+사창리!H14+대원건설!H14+정윤일!H14+비고1!H14+비고2!H14,"") | I14: =IF(만두건설!I14+만두토목!I14+홍천서석!I14+사창리!I14+대원건설!I14+정윤일!I14+비고1!I14+비고2!I14>0,만두건설!I14+만두토목!I14+홍천서석!I14+사창리!I14+대원건설!I14+정윤일!I14+비고1!I14+비고2!I14,"") | J14: =IF(만두건설!J14+만두토목!J14+홍천서석!J14+사창리!J14+대원건설!J14+정윤일!J14+비고1!J14+비고2!J14>0,만두건설!J14+만두토목!J14+홍천서석!J14+사창리!J14+대원건설!J14+정윤일!J14+비고1!J14+비고2!J14,"") | K14: =IF(만두건설!K14+만두토목!K14+홍천서석!K14+사창리!K14+대원건설!K14+정윤일!K14+비고1!K14+비고2!K14>0,만두건설!K14+만두토목!K14+홍천서석!K14+사창리!K14+대원건설!K14+정윤일!K14+비고1!K14+비고2!K14,"") | L14: =IF(만두건설!L14+만두토목!L14+홍천서석!L14+사창리!L14+대원건설!L14+정윤일!L14+비고1!L14+비고2!L14>0,만두건설!L14+만두토목!L14+홍천서석!L14+사창리!L14+대원건설!L14+정윤일!L14+비고1!L14+비고2!L14,"") | M14: =IF(만두건설!M14+만두토목!M14+홍천서석!M14+사창리!M14+대원건설!M14+정윤일!M14+비고1!M14+비고2!M14>0,만두건설!M14+만두토목!M14+홍천서석!M14+사창리!M14+대원건설!M14+정윤일!M14+비고1!M14+비고2!M14,"") | N14: =IF(만두건설!N14+만두토목!N14+홍천서석!N14+사창리!N14+대원건설!N14+정윤일!N14+비고1!N14+비고2!N14>0,만두건설!N14+만두토목!N14+홍천서석!N14+사창리!N14+대원건설!N14+정윤일!N14+비고1!N14+비고2!N14,"") | ... AK14: =IF(만두건설!AK14+만두토목!AK14+홍천서석!AK14+사창리!AK14+대원건설!AK14+정윤일!AK14+비고1!AK14+비고2!AK14>0,만두건설!AK14+만두토목!AK14+홍천서석!AK14+사창리!AK14+대원건설!AK14+정윤일!AK14+비고1!AK14+비고2!AK14,"") | AL14: =IF(SUM(G14:AK14)>0,SUM(G14:AK14),"") | AN14: =(COUNT(G14:AK14)) -> 0 | AP14: =IF(만두건설!AL14>0,만두건설!AL14,"") | AR14: =IF(만두토목!AL14>0,만두토목!AL14,"") | AT14: =IF(홍천서석!AL14>0,홍천서석!AL14,"") | AV14: =IF(사창리!AL14>0,사창리!AL14,"") | AX14: =IF(대원건설!AL14>0,대원건설!AL14,"") | AZ14: =IF(정윤일!AL14>0,정윤일!AL14,"") | BB14: =IF(비고1!AL14>0,비고1!AL14,"") | BD14: =IF(비고2!AL14>0,비고2!AL14,"")
A15: =ROW()-5 -> 10 | C15: 윤지아 | G15: =IF(만두건설!G15+만두토목!G15+홍천서석!G15+사창리!G15+대원건설!G15+정윤일!G15+비고1!G15+비고2!G15>0,만두건설!G15+만두토목!G15+홍천서석!G15+사창리!G15+대원건설!G15+정윤일!G15+비고1!G15+비고2!G15,"") | H15: =IF(만두건설!H15+만두토목!H15+홍천서석!H15+사창리!H15+대원건설!H15+정윤일!H15+비고1!H15+비고2!H15>0,만두건설!H15+만두토목!H15+홍천서석!H15+사창리!H15+대원건설!H15+정윤일!H15+비고1!H15+비고2!H15,"") | I15: =IF(만두건설!I15+만두토목!I15+홍천서석!I15+사창리!I15+대원건설!I15+정윤일!I15+비고1!I15+비고2!I15>0,만두건설!I15+만두토목!I15+홍천서석!I15+사창리!I15+대원건설!I15+정윤일!I15+비고1!I15+비고2!I15,"") | J15: =IF(만두건설!J15+만두토목!J15+홍천서석!J15+사창리!J15+대원건설!J15+정윤일!J15+비고1!J15+비고2!J15>0,만두건설!J15+만두토목!J15+홍천서석!J15+사창리!J15+대원건설!J15+정윤일!J15+비고1!J15+비고2!J15,"") | K15: =IF(만두건설!K15+만두토목!K15+홍천서석!K15+사창리!K15+대원건설!K15+정윤일!K15+비고1!K15+비고2!K15>0,만두건설!K15+만두토목!K15+홍천서석!K15+사창리!K15+대원건설!K15+정윤일!K15+비고1!K15+비고2!K15,"") | L15: =IF(만두건설!L15+만두토목!L15+홍천서석!L15+사창리!L15+대원건설!L15+정윤일!L15+비고1!L15+비고2!L15>0,만두건설!L15+만두토목!L15+홍천서석!L15+사창리!L15+대원건설!L15+정윤일!L15+비고1!L15+비고2!L15,"") | M15: =IF(만두건설!M15+만두토목!M15+홍천서석!M15+사창리!M15+대원건설!M15+정윤일!M15+비고1!M15+비고2!M15>0,만두건설!M15+만두토목!M15+홍천서석!M15+사창리!M15+대원건설!M15+정윤일!M15+비고1!M15+비고2!M15,"") | N15: =IF(만두건설!N15+만두토목!N15+홍천서석!N15+사창리!N15+대원건설!N15+정윤일!N15+비고1!N15+비고2!N15>0,만두건설!N15+만두토목!N15+홍천서석!N15+사창리!N15+대원건설!N15+정윤일!N15+비고1!N15+비고2!N15,"") | ... AK15: =IF(만두건설!AK15+만두토목!AK15+홍천서석!AK15+사창리!AK15+대원건설!AK15+정윤일!AK15+비고1!AK15+비고2!AK15>0,만두건설!AK15+만두토목!AK15+홍천서석!AK15+사창리!AK15+대원건설!AK15+정윤일!AK15+비고1!AK15+비고2!AK15,"") | AL15: =IF(SUM(G15:AK15)>0,SUM(G15:AK15),"") | AN15: =(COUNT(G15:AK15)) -> 0 | AP15: =IF(만두건설!AL15>0,만두건설!AL15,"") | AR15: =IF(만두토목!AL15>0,만두토목!AL15,"") | AT15: =IF(홍천서석!AL15>0,홍천서석!AL15,"") | AV15: =IF(사창리!AL15>0,사창리!AL15,"") | AX15: =IF(대원건설!AL15>0,대원건설!AL15,"") | AZ15: =IF(정윤일!AL15>0,정윤일!AL15,"") | BB15: =IF(비고1!AL15>0,비고1!AL15,"") | BD15: =IF(비고2!AL15>0,비고2!AL15,"")
A16: =ROW()-5 -> 11 | C16: 임동현 | G16: =IF(만두건설!G16+만두토목!G16+홍천서석!G16+사창리!G16+대원건설!G16+정윤일!G16+비고1!G16+비고2!G16>0,만두건설!G16+만두토목!G16+홍천서석!G16+사창리!G16+대원건설!G16+정윤일!G16+비고1!G16+비고2!G16,"") | H16: =IF(만두건설!H16+만두토목!H16+홍천서석!H16+사창리!H16+대원건설!H16+정윤일!H16+비고1!H16+비고2!H16>0,만두건설!H16+만두토목!H16+홍천서석!H16+사창리!H16+대원건설!H16+정윤일!H16+비고1!H16+비고2!H16,"") | I16: =IF(만두건설!I16+만두토목!I16+홍천서석!I16+사창리!I16+대원건설!I16+정윤일!I16+비고1!I16+비고2!I16>0,만두건설!I16+만두토목!I16+홍천서석!I16+사창리!I16+대원건설!I16+정윤일!I16+비고1!I16+비고2!I16,"") | J16: =IF(만두건설!J16+만두토목!J16+홍천서석!J16+사창리!J16+대원건설!J16+정윤일!J16+비고1!J16+비고2!J16>0,만두건설!J16+만두토목!J16+홍천서석!J16+사창리!J16+대원건설!J16+정윤일!J16+비고1!J16+비고2!J16,"") | K16: =IF(만두건설!K16+만두토목!K16+홍천서석!K16+사창리!K16+대원건설!K16+정윤일!K16+비고1!K16+비고2!K16>0,만두건설!K16+만두토목!K16+홍천서석!K16+사창리!K16+대원건설!K16+정윤일!K16+비고1!K16+비고2!K16,"") | L16: =IF(만두건설!L16+만두토목!L16+홍천서석!L16+사창리!L16+대원건설!L16+정윤일!L16+비고1!L16+비고2!L16>0,만두건설!L16+만두토목!L16+홍천서석!L16+사창리!L16+대원건설!L16+정윤일!L16+비고1!L16+비고2!L16,"") | M16: =IF(만두건설!M16+만두토목!M16+홍천서석!M16+사창리!M16+대원건설!M16+정윤일!M16+비고1!M16+비고2!M16>0,만두건설!M16+만두토목!M16+홍천서석!M16+사창리!M16+대원건설!M16+정윤일!M16+비고1!M16+비고2!M16,"") | N16: =IF(만두건설!N16+만두토목!N16+홍천서석!N16+사창리!N16+대원건설!N16+정윤일!N16+비고1!N16+비고2!N16>0,만두건설!N16+만두토목!N16+홍천서석!N16+사창리!N16+대원건설!N16+정윤일!N16+비고1!N16+비고2!N16,"") | ... AK16: =IF(만두건설!AK16+만두토목!AK16+홍천서석!AK16+사창리!AK16+대원건설!AK16+정윤일!AK16+비고1!AK16+비고2!AK16>0,만두건설!AK16+만두토목!AK16+홍천서석!AK16+사창리!AK16+대원건설!AK16+정윤일!AK16+비고1!AK16+비고2!AK16,"") | AL16: =IF(SUM(G16:AK16)>0,SUM(G16:AK16),"") | AN16: =(COUNT(G16:AK16)) -> 0 | AP16: =IF(만두건설!AL16>0,만두건설!AL16,"") | AR16: =IF(만두토목!AL16>0,만두토목!AL16,"") | AT16: =IF(홍천서석!AL16>0,홍천서석!AL16,"") | AV16: =IF(사창리!AL16>0,사창리!AL16,"") | AX16: =IF(대원건설!AL16>0,대원건설!AL16,"") | AZ16: =IF(정윤일!AL16>0,정윤일!AL16,"") | BB16: =IF(비고1!AL16>0,비고1!AL16,"") | BD16: =IF(비고2!AL16>0,비고2!AL16,"")
A17: =ROW()-5 -> 12 | C17: 심유진 | G17: =IF(만두건설!G17+만두토목!G17+홍천서석!G17+사창리!G17+대원건설!G17+정윤일!G17+비고1!G17+비고2!G17>0,만두건설!G17+만두토목!G17+홍천서석!G17+사창리!G17+대원건설!G17+정윤일!G17+비고1!G17+비고2!G17,"") | H17: =IF(만두건설!H17+만두토목!H17+홍천서석!H17+사창리!H17+대원건설!H17+정윤일!H17+비고1!H17+비고2!H17>0,만두건설!H17+만두토목!H17+홍천서석!H17+사창리!H17+대원건설!H17+정윤일!H17+비고1!H17+비고2!H17,"") | I17: =IF(만두건설!I17+만두토목!I17+홍천서석!I17+사창리!I17+대원건설!I17+정윤일!I17+비고1!I17+비고2!I17>0,만두건설!I17+만두토목!I17+홍천서석!I17+사창리!I17+대원건설!I17+정윤일!I17+비고1!I17+비고2!I17,"") | J17: =IF(만두건설!J17+만두토목!J17+홍천서석!J17+사창리!J17+대원건설!J17+정윤일!J17+비고1!J17+비고2!J17>0,만두건설!J17+만두토목!J17+홍천서석!J17+사창리!J17+대원건설!J17+정윤일!J17+비고1!J17+비고2!J17,"") | K17: =IF(만두건설!K17+만두토목!K17+홍천서석!K17+사창리!K17+대원건설!K17+정윤일!K17+비고1!K17+비고2!K17>0,만두건설!K17+만두토목!K17+홍천서석!K17+사창리!K17+대원건설!K17+정윤일!K17+비고1!K17+비고2!K17,"") | L17: =IF(만두건설!L17+만두토목!L17+홍천서석!L17+사창리!L17+대원건설!L17+정윤일!L17+비고1!L17+비고2!L17>0,만두건설!L17+만두토목!L17+홍천서석!L17+사창리!L17+대원건설!L17+정윤일!L17+비고1!L17+비고2!L17,"") | M17: =IF(만두건설!M17+만두토목!M17+홍천서석!M17+사창리!M17+대원건설!M17+정윤일!M17+비고1!M17+비고2!M17>0,만두건설!M17+만두토목!M17+홍천서석!M17+사창리!M17+대원건설!M17+정윤일!M17+비고1!M17+비고2!M17,"") | N17: =IF(만두건설!N17+만두토목!N17+홍천서석!N17+사창리!N17+대원건설!N17+정윤일!N17+비고1!N17+비고2!N17>0,만두건설!N17+만두토목!N17+홍천서석!N17+사창리!N17+대원건설!N17+정윤일!N17+비고1!N17+비고2!N17,"") | ... AK17: =IF(만두건설!AK17+만두토목!AK17+홍천서석!AK17+사창리!AK17+대원건설!AK17+정윤일!AK17+비고1!AK17+비고2!AK17>0,만두건설!AK17+만두토목!AK17+홍천서석!AK17+사창리!AK17+대원건설!AK17+정윤일!AK17+비고1!AK17+비고2!AK17,"") | AL17: =IF(SUM(G17:AK17)>0,SUM(G17:AK17),"") | AN17: =(COUNT(G17:AK17)) -> 0 | AP17: =IF(만두건설!AL17>0,만두건설!AL17,"") | AR17: =IF(만두토목!AL17>0,만두토목!AL17,"") | AT17: =IF(홍천서석!AL17>0,홍천서석!AL17,"") | AV17: =IF(사창리!AL17>0,사창리!AL17,"") | AX17: =IF(대원건설!AL17>0,대원건설!AL17,"") | AZ17: =IF(정윤일!AL17>0,정윤일!AL17,"") | BB17: =IF(비고1!AL17>0,비고1!AL17,"") | BD17: =IF(비고2!AL17>0,비고2!AL17,"")
